Workbook

Sheet Cash & runway
A1: Cash & runway
A2: Cash & Runway · Main Scenario
A4: Variable / dimension | B4: 2026-10 | C4: 2026-11 | D4: 2026-12 | E4: 2027-01 | F4: 2027-02 | G4: 2027-03 | H4: 2027-04 | I4: 2027-05 | J4: 2027-06 | K4: 2027-07 | L4: 2027-08 | M4: 2027-09 | N4: 2027-10 | O4: 2027-11 | P4: 2027-12 | Q4: 2028-01 | R4: 2028-02 | S4: 2028-03 | T4: 2028-04 | U4: 2028-05 | V4: 2028-06 | W4: 2028-07 | X4: 2028-08 | Y4: 2028-09
A5: Gross profit | B5: ='Model inputs'!D22-'Model inputs'!D10 -> 0 | C5: ='Model inputs'!E22-'Model inputs'!E10 -> 149.85 | D5: ='Model inputs'!F22-'Model inputs'!F10 -> 149.85 | E5: ='Model inputs'!G22-'Model inputs'!G10 -> 149.85 | F5: ='Model inputs'!H22-'Model inputs'!H10 -> 149.85 | G5: ='Model inputs'!I22-'Model inputs'!I10 -> 149.85 | H5: ='Model inputs'!J22-'Model inputs'!J10 -> 149.85 | I5: ='Model inputs'!K22-'Model inputs'!K10 -> 149.85 | ... Y5: ='Model inputs'!AA22-'Model inputs'!AA10 -> 149.85
A6: Fixed costs | B6: =SUM('Model inputs'!D12,'Model inputs'!D13,'Model inputs'!D14,'Model inputs'!D15) -> 170 | C6: =SUM('Model inputs'!E12,'Model inputs'!E13,'Model inputs'!E14,'Model inputs'!E15) -> 170 | D6: =SUM('Model inputs'!F12,'Model inputs'!F13,'Model inputs'!F14,'Model inputs'!F15) -> 170 | E6: =SUM('Model inputs'!G12,'Model inputs'!G13,'Model inputs'!G14,'Model inputs'!G15) -> 170 | F6: =SUM('Model inputs'!H12,'Model inputs'!H13,'Model inputs'!H14,'Model inputs'!H15) -> 170 | G6: =SUM('Model inputs'!I12,'Model inputs'!I13,'Model inputs'!I14,'Model inputs'!I15) -> 170 | H6: =SUM('Model inputs'!J12,'Model inputs'!J13,'Model inputs'!J14,'Model inputs'!J15) -> 170 | I6: =SUM('Model inputs'!K12,'Model inputs'!K13,'Model inputs'!K14,'Model inputs'!K15) -> 170 | ... Y6: =SUM('Model inputs'!AA12,'Model inputs'!AA13,'Model inputs'!AA14,'Model inputs'!AA15) -> 170
A7: Operating profit | B7: ='Cash & runway'!B5-'Cash & runway'!B6 -> -170 | C7: ='Cash & runway'!C5-'Cash & runway'!C6 -> -20.15 | D7: ='Cash & runway'!D5-'Cash & runway'!D6 -> -20.15 | E7: ='Cash & runway'!E5-'Cash & runway'!E6 -> -20.15 | F7: ='Cash & runway'!F5-'Cash & runway'!F6 -> -20.15 | G7: ='Cash & runway'!G5-'Cash & runway'!G6 -> -20.15 | H7: ='Cash & runway'!H5-'Cash & runway'!H6 -> -20.15 | I7: ='Cash & runway'!I5-'Cash & runway'!I6 -> -20.15 | ... Y7: ='Cash & runway'!Y5-'Cash & runway'!Y6 -> -20.15
A9: Cash collected from customers | B9: ='Model inputs'!C22*(1-'Model inputs'!B21) -> 0 | C9: ='Model inputs'!D22*(1-'Model inputs'!B21) -> 0 | D9: ='Model inputs'!E22*(1-'Model inputs'!B21) -> 247.35 | E9: ='Model inputs'!F22*(1-'Model inputs'!B21) -> 247.35 | F9: ='Model inputs'!G22*(1-'Model inputs'!B21) -> 247.35 | G9: ='Model inputs'!H22*(1-'Model inputs'!B21) -> 247.35 | H9: ='Model inputs'!I22*(1-'Model inputs'!B21) -> 247.35 | I9: ='Model inputs'!J22*(1-'Model inputs'!B21) -> 247.35 | J9: ='Model inputs'!K22*(1-'Model inputs'!B21) -> 247.35 | K9: ='Model inputs'!L22*(1-'Model inputs'!B21) -> 247.35 | L9: ='Model inputs'!M22*(1-'Model inputs'!B21) -> 247.35 | M9: ='Model inputs'!N22*(1-'Model inputs'!B21) -> 247.35 | N9: ='Model inputs'!O22*(1-'Model inputs'!B21) -> 247.35 | O9: ='Model inputs'!P22*(1-'Model inputs'!B21) -> 247.35 | P9: ='Model inputs'!Q22*(1-'Model inputs'!B21) -> 247.35 | Q9: ='Model inputs'!R22*(1-'Model inputs'!B21) -> 247.35 | R9: ='Model inputs'!S22*(1-'Model inputs'!B21) -> 247.35 | S9: ='Model inputs'!T22*(1-'Model inputs'!B21) -> 247.35 | T9: ='Model inputs'!U22*(1-'Model inputs'!B21) -> 247.35 | U9: ='Model inputs'!V22*(1-'Model inputs'!B21) -> 247.35 | V9: ='Model inputs'!W22*(1-'Model inputs'!B21) -> 247.35 | W9: ='Model inputs'!X22*(1-'Model inputs'!B21) -> 247.35 | X9: ='Model inputs'!Y22*(1-'Model inputs'!B21) -> 247.35 | Y9: ='Model inputs'!Z22*(1-'Model inputs'!B21) -> 247.35
A10: Model usage cost | B10: ='Model inputs'!D23*'Model inputs'!B6 -> 0 | C10: ='Model inputs'!E23*'Model inputs'!B6 -> 97.5 | D10: ='Model inputs'!F23*'Model inputs'!B6 -> 97.5 | E10: ='Model inputs'!G23*'Model inputs'!B6 -> 97.5 | F10: ='Model inputs'!H23*'Model inputs'!B6 -> 97.5 | G10: ='Model inputs'!I23*'Model inputs'!B6 -> 97.5 | H10: ='Model inputs'!J23*'Model inputs'!B6 -> 97.5 | I10: ='Model inputs'!K23*'Model inputs'!B6 -> 97.5 | J10: ='Model inputs'!L23*'Model inputs'!B6 -> 97.5 | K10: ='Model inputs'!M23*'Model inputs'!B6 -> 97.5 | L10: ='Model inputs'!N23*'Model inputs'!B6 -> 97.5 | M10: ='Model inputs'!O23*'Model inputs'!B6 -> 97.5 | N10: ='Model inputs'!P23*'Model inputs'!B6 -> 97.5 | O10: ='Model inputs'!Q23*'Model inputs'!B6 -> 97.5 | P10: ='Model inputs'!R23*'Model inputs'!B6 -> 97.5 | Q10: ='Model inputs'!S23*'Model inputs'!B6 -> 97.5 | R10: ='Model inputs'!T23*'Model inputs'!B6 -> 97.5 | S10: ='Model inputs'!U23*'Model inputs'!B6 -> 97.5 | T10: ='Model inputs'!V23*'Model inputs'!B6 -> 97.5 | U10: ='Model inputs'!W23*'Model inputs'!B6 -> 97.5 | V10: ='Model inputs'!X23*'Model inputs'!B6 -> 97.5 | W10: ='Model inputs'!Y23*'Model inputs'!B6 -> 97.5 | X10: ='Model inputs'!Z23*'Model inputs'!B6 -> 97.5 | Y10: ='Model inputs'!AA23*'Model inputs'!B6 -> 97.5
A11: Net cash flow | B11: ='Cash & runway'!B9-'Cash & runway'!B10-'Cash & runway'!B6 -> -170 | C11: ='Cash & runway'!C9-'Cash & runway'!C10-'Cash & runway'!C6 -> -267.5 | D11: ='Cash & runway'!D9-'Cash & runway'!D10-'Cash & runway'!D6 -> -20.15 | E11: ='Cash & runway'!E9-'Cash & runway'!E10-'Cash & runway'!E6 -> -20.15 | F11: ='Cash & runway'!F9-'Cash & runway'!F10-'Cash & runway'!F6 -> -20.15 | G11: ='Cash & runway'!G9-'Cash & runway'!G10-'Cash & runway'!G6 -> -20.15 | H11: ='Cash & runway'!H9-'Cash & runway'!H10-'Cash & runway'!H6 -> -20.15 | I11: ='Cash & runway'!I9-'Cash & runway'!I10-'Cash & runway'!I6 -> -20.15 | ... Y11: ='Cash & runway'!Y9-'Cash & runway'!Y10-'Cash & runway'!Y6 -> -20.15
A12: Cash balance | B12: ='Model inputs'!C7+'Cash & runway'!B11 -> 2830 | C12: ='Cash & runway'!B12+'Cash & runway'!C11 -> 2562.5 | D12: ='Cash & runway'!C12+'Cash & runway'!D11 -> 2542.35 | E12: ='Cash & runway'!D12+'Cash & runway'!E11 -> 2522.2 | F12: ='Cash & runway'!E12+'Cash & runway'!F11 -> 2502.05 | G12: ='Cash & runway'!F12+'Cash & runway'!G11 -> 2481.9 | H12: ='Cash & runway'!G12+'Cash & runway'!H11 -> 2461.75 | I12: ='Cash & runway'!H12+'Cash & runway'!I11 -> 2441.6 | J12: ='Cash & runway'!I12+'Cash & runway'!J11 -> 2421.45 | ... Y12: ='Cash & runway'!X12+'Cash & runway'!Y11 -> 2119.2
A13: Runway (months) | B13: =IF(IF(IF(ISERROR('Cash & runway'!B12<=0),'Cash & runway'!B12<=0,IF('Cash & runway'!B12="","",'Cash & runway'!B12<=0))="",FALSE,IF(ISERROR('Cash & runway'!B12<=0),'Cash & runway'!B12<=0,IF('Cash & runway'!B12="","",'Cash & runway'!B12<=0))),0,IF(IF(IF(ISERROR('Cash & runway'!B11>=0),'Cash & runway'!B11>=0,IF('Cash & runway'!B11="","",'Cash & runway'!B11>=0))="",FALSE,IF(ISERROR('Cash & runway'!B11>=0),'Cash & runway'!B11>=0,IF('Cash & runway'!B11="","",'Cash & runway'!B11>=0))),"",'Cash & runway'!B12/-'Cash & runway'!B11)) -> 16.647059 | C13: =IF(IF(IF(ISERROR('Cash & runway'!C12<=0),'Cash & runway'!C12<=0,IF('Cash & runway'!C12="","",'Cash & runway'!C12<=0))="",FALSE,IF(ISERROR('Cash & runway'!C12<=0),'Cash & runway'!C12<=0,IF('Cash & runway'!C12="","",'Cash & runway'!C12<=0))),0,IF(IF(IF(ISERROR('Cash & runway'!C11>=0),'Cash & runway'!C11>=0,IF('Cash & runway'!C11="","",'Cash & runway'!C11>=0))="",FALSE,IF(ISERROR('Cash & runway'!C11>=0),'Cash & runway'!C11>=0,IF('Cash & runway'!C11="","",'Cash & runway'!C11>=0))),"",'Cash & runway'!C12/-'Cash & runway'!C11)) -> 9.5794393 | D13: =IF(IF(IF(ISERROR('Cash & runway'!D12<=0),'Cash & runway'!D12<=0,IF('Cash & runway'!D12="","",'Cash & runway'!D12<=0))="",FALSE,IF(ISERROR('Cash & runway'!D12<=0),'Cash & runway'!D12<=0,IF('Cash & runway'!D12="","",'Cash & runway'!D12<=0))),0,IF(IF(IF(ISERROR('Cash & runway'!D11>=0),'Cash & runway'!D11>=0,IF('Cash & runway'!D11="","",'Cash & runway'!D11>=0))="",FALSE,IF(ISERROR('Cash & runway'!D11>=0),'Cash & runway'!D11>=0,IF('Cash & runway'!D11="","",'Cash & runway'!D11>=0))),"",'Cash & runway'!D12/-'Cash & runway'!D11)) -> 126.17122 | E13: =IF(IF(IF(ISERROR('Cash & runway'!E12<=0),'Cash & runway'!E12<=0,IF('Cash & runway'!E12="","",'Cash & runway'!E12<=0))="",FALSE,IF(ISERROR('Cash & runway'!E12<=0),'Cash & runway'!E12<=0,IF('Cash & runway'!E12="","",'Cash & runway'!E12<=0))),0,IF(IF(IF(ISERROR('Cash & runway'!E11>=0),'Cash & runway'!E11>=0,IF('Cash & runway'!E11="","",'Cash & runway'!E11>=0))="",FALSE,IF(ISERROR('Cash & runway'!E11>=0),'Cash & runway'!E11>=0,IF('Cash & runway'!E11="","",'Cash & runway'!E11>=0))),"",'Cash & runway'!E12/-'Cash & runway'!E11)) -> 125.17122 | F13: =IF(IF(IF(ISERROR('Cash & runway'!F12<=0),'Cash & runway'!F12<=0,IF('Cash & runway'!F12="","",'Cash & runway'!F12<=0))="",FALSE,IF(ISERROR('Cash & runway'!F12<=0),'Cash & runway'!F12<=0,IF('Cash & runway'!F12="","",'Cash & runway'!F12<=0))),0,IF(IF(IF(ISERROR('Cash & runway'!F11>=0),'Cash & runway'!F11>=0,IF('Cash & runway'!F11="","",'Cash & runway'!F11>=0))="",FALSE,IF(ISERROR('Cash & runway'!F11>=0),'Cash & runway'!F11>=0,IF('Cash & runway'!F11="","",'Cash & runway'!F11>=0))),"",'Cash & runway'!F12/-'Cash & runway'!F11)) -> 124.17122 | G13: =IF(IF(IF(ISERROR('Cash & runway'!G12<=0),'Cash & runway'!G12<=0,IF('Cash & runway'!G12="","",'Cash & runway'!G12<=0))="",FALSE,IF(ISERROR('Cash & runway'!G12<=0),'Cash & runway'!G12<=0,IF('Cash & runway'!G12="","",'Cash & runway'!G12<=0))),0,IF(IF(IF(ISERROR('Cash & runway'!G11>=0),'Cash & runway'!G11>=0,IF('Cash & runway'!G11="","",'Cash & runway'!G11>=0))="",FALSE,IF(ISERROR('Cash & runway'!G11>=0),'Cash & runway'!G11>=0,IF('Cash & runway'!G11="","",'Cash & runway'!G11>=0))),"",'Cash & runway'!G12/-'Cash & runway'!G11)) -> 123.17122 | H13: =IF(IF(IF(ISERROR('Cash & runway'!H12<=0),'Cash & runway'!H12<=0,IF('Cash & runway'!H12="","",'Cash & runway'!H12<=0))="",FALSE,IF(ISERROR('Cash & runway'!H12<=0),'Cash & runway'!H12<=0,IF('Cash & runway'!H12="","",'Cash & runway'!H12<=0))),0,IF(IF(IF(ISERROR('Cash & runway'!H11>=0),'Cash & runway'!H11>=0,IF('Cash & runway'!H11="","",'Cash & runway'!H11>=0))="",FALSE,IF(ISERROR('Cash & runway'!H11>=0),'Cash & runway'!H11>=0,IF('Cash & runway'!H11="","",'Cash & runway'!H11>=0))),"",'Cash & runway'!H12/-'Cash & runway'!H11)) -> 122.17122 | I13: =IF(IF(IF(ISERROR('Cash & runway'!I12<=0),'Cash & runway'!I12<=0,IF('Cash & runway'!I12="","",'Cash & runway'!I12<=0))="",FALSE,IF(ISERROR('Cash & runway'!I12<=0),'Cash & runway'!I12<=0,IF('Cash & runway'!I12="","",'Cash & runway'!I12<=0))),0,IF(IF(IF(ISERROR('Cash & runway'!I11>=0),'Cash & runway'!I11>=0,IF('Cash & runway'!I11="","",'Cash & runway'!I11>=0))="",FALSE,IF(ISERROR('Cash & runway'!I11>=0),'Cash & runway'!I11>=0,IF('Cash & runway'!I11="","",'Cash & runway'!I11>=0))),"",'Cash & runway'!I12/-'Cash & runway'!I11)) -> 121.17122 | ... Y13: =IF(IF(IF(ISERROR('Cash & runway'!Y12<=0),'Cash & runway'!Y12<=0,IF('Cash & runway'!Y12="","",'Cash & runway'!Y12<=0))="",FALSE,IF(ISERROR('Cash & runway'!Y12<=0),'Cash & runway'!Y12<=0,IF('Cash & runway'!Y12="","",'Cash & runway'!Y12<=0))),0,IF(IF(IF(ISERROR('Cash & runway'!Y11>=0),'Cash & runway'!Y11>=0,IF('Cash & runway'!Y11="","",'Cash & runway'!Y11>=0))="",FALSE,IF(ISERROR('Cash & runway'!Y11>=0),'Cash & runway'!Y11>=0,IF('Cash & runway'!Y11="","",'Cash & runway'!Y11>=0))),"",'Cash & runway'!Y12/-'Cash & runway'!Y11)) -> 105.17122

Sheet Cash with $2,000 founder salary
A1: Cash with $2,000 founder salary
A2: Cash & Runway · Main Scenario
A4: Variable / dimension | B4: 2026-10 | C4: 2026-11 | D4: 2026-12 | E4: 2027-01 | F4: 2027-02 | G4: 2027-03 | H4: 2027-04 | I4: 2027-05 | J4: 2027-06 | K4: 2027-07 | L4: 2027-08 | M4: 2027-09 | N4: 2027-10 | O4: 2027-11 | P4: 2027-12 | Q4: 2028-01 | R4: 2028-02 | S4: 2028-03 | T4: 2028-04 | U4: 2028-05 | V4: 2028-06 | W4: 2028-07 | X4: 2028-08 | Y4: 2028-09
A5: Net cash flow | B5: ='Cash & runway'!B9-'Cash & runway'!B10-'Cash & runway'!B6 -> -170 | C5: ='Cash & runway'!C9-'Cash & runway'!C10-'Cash & runway'!C6 -> -267.5 | D5: ='Cash & runway'!D9-'Cash & runway'!D10-'Cash & runway'!D6 -> -20.15 | E5: ='Cash & runway'!E9-'Cash & runway'!E10-'Cash & runway'!E6 -> -20.15 | F5: ='Cash & runway'!F9-'Cash & runway'!F10-'Cash & runway'!F6 -> -20.15 | G5: ='Cash & runway'!G9-'Cash & runway'!G10-'Cash & runway'!G6 -> -20.15 | H5: ='Cash & runway'!H9-'Cash & runway'!H10-'Cash & runway'!H6 -> -20.15 | I5: ='Cash & runway'!I9-'Cash & runway'!I10-'Cash & runway'!I6 -> -20.15 | ... Y5: ='Cash & runway'!Y9-'Cash & runway'!Y10-'Cash & runway'!Y6 -> -20.15
A6: Founder salary | B6: =IF('Model inputs'!B17="","",'Model inputs'!B17) -> 2000 | C6: =IF('Model inputs'!B17="","",'Model inputs'!B17) -> 2000 | D6: =IF('Model inputs'!B17="","",'Model inputs'!B17) -> 2000 | E6: =IF('Model inputs'!B17="","",'Model inputs'!B17) -> 2000 | F6: =IF('Model inputs'!B17="","",'Model inputs'!B17) -> 2000 | G6: =IF('Model inputs'!B17="","",'Model inputs'!B17) -> 2000 | H6: =IF('Model inputs'!B17="","",'Model inputs'!B17) -> 2000 | I6: =IF('Model inputs'!B17="","",'Model inputs'!B17) -> 2000 | J6: =IF('Model inputs'!B17="","",'Model inputs'!B17) -> 2000 | K6: =IF('Model inputs'!B17="","",'Model inputs'!B17) -> 2000 | L6: =IF('Model inputs'!B17="","",'Model inputs'!B17) -> 2000 | M6: =IF('Model inputs'!B17="","",'Model inputs'!B17) -> 2000 | N6: =IF('Model inputs'!B17="","",'Model inputs'!B17) -> 2000 | O6: =IF('Model inputs'!B17="","",'Model inputs'!B17) -> 2000 | P6: =IF('Model inputs'!B17="","",'Model inputs'!B17) -> 2000 | Q6: =IF('Model inputs'!B17="","",'Model inputs'!B17) -> 2000 | R6: =IF('Model inputs'!B17="","",'Model inputs'!B17) -> 2000 | S6: =IF('Model inputs'!B17="","",'Model inputs'!B17) -> 2000 | T6: =IF('Model inputs'!B17="","",'Model inputs'!B17) -> 2000 | U6: =IF('Model inputs'!B17="","",'Model inputs'!B17) -> 2000 | V6: =IF('Model inputs'!B17="","",'Model inputs'!B17) -> 2000 | W6: =IF('Model inputs'!B17="","",'Model inputs'!B17) -> 2000 | X6: =IF('Model inputs'!B17="","",'Model inputs'!B17) -> 2000 | Y6: =IF('Model inputs'!B17="","",'Model inputs'!B17) -> 2000
A7: Net cash flow with salary | B7: ='Cash with $2,000 founder salary'!B5-'Cash with $2,000 founder salary'!B6 -> -2170 | C7: ='Cash with $2,000 founder salary'!C5-'Cash with $2,000 founder salary'!C6 -> -2267.5 | D7: ='Cash with $2,000 founder salary'!D5-'Cash with $2,000 founder salary'!D6 -> -2020.15 | E7: ='Cash with $2,000 founder salary'!E5-'Cash with $2,000 founder salary'!E6 -> -2020.15 | F7: ='Cash with $2,000 founder salary'!F5-'Cash with $2,000 founder salary'!F6 -> -2020.15 | G7: ='Cash with $2,000 founder salary'!G5-'Cash with $2,000 founder salary'!G6 -> -2020.15 | H7: ='Cash with $2,000 founder salary'!H5-'Cash with $2,000 founder salary'!H6 -> -2020.15 | I7: ='Cash with $2,000 founder salary'!I5-'Cash with $2,000 founder salary'!I6 -> -2020.15 | ... Y7: ='Cash with $2,000 founder salary'!Y5-'Cash with $2,000 founder salary'!Y6 -> -2020.15
A8: Cash balance with salary | B8: ='Model inputs'!C8+'Cash with $2,000 founder salary'!B7 -> 830 | C8: ='Cash with $2,000 founder salary'!B8+'Cash with $2,000 founder salary'!C7 -> -1437.5 | D8: ='Cash with $2,000 founder salary'!C8+'Cash with $2,000 founder salary'!D7 -> -3457.65 | E8: ='Cash with $2,000 founder salary'!D8+'Cash with $2,000 founder salary'!E7 -> -5477.8 | F8: ='Cash with $2,000 founder salary'!E8+'Cash with $2,000 founder salary'!F7 -> -7497.95 | G8: ='Cash with $2,000 founder salary'!F8+'Cash with $2,000 founder salary'!G7 -> -9518.1 | H8: ='Cash with $2,000 founder salary'!G8+'Cash with $2,000 founder salary'!H7 -> -11538.25 | I8: ='Cash with $2,000 founder salary'!H8+'Cash with $2,000 founder salary'!I7 -> -13558.4 | J8: ='Cash with $2,000 founder salary'!I8+'Cash with $2,000 founder salary'!J7 -> -15578.55 | ... Y8: ='Cash with $2,000 founder salary'!X8+'Cash with $2,000 founder salary'!Y7 -> -45880.8
A9: Runway with salary (months) | B9: =IF(IF(IF(ISERROR('Cash with $2,000 founder salary'!B8<=0),'Cash with $2,000 founder salary'!B8<=0,IF('Cash with $2,000 founder salary'!B8="","",'Cash with $2,000 founder salary'!B8<=0))="",FALSE,IF(ISERROR('Cash with $2,000 founder salary'!B8<=0),'Cash with $2,000 founder salary'!B8<=0,IF('Cash with $2,000 founder salary'!B8="","",'Cash with $2,000 founder salary'!B8<=0))),0,IF(IF(IF(ISERROR('Cash with $2,000 founder salary'!B7>=0),'Cash with $2,000 founder salary'!B7>=0,IF('Cash with $2,000 founder salary'!B7="","",'Cash with $2,000 founder salary'!B7>=0))="",FALSE,IF(ISERROR('Cash with $2,000 founder salary'!B7>=0),'Cash with $2,000 founder salary'!B7>=0,IF('Cash with $2,000 founder salary'!B7="","",'Cash with $2,000 founder salary'!B7>=0))),"",'Cash with $2,000 founder salary'!B8/-'Cash with $2,000 founder salary'!B7)) -> 0.38248848 | C9: =IF(IF(IF(ISERROR('Cash with $2,000 founder salary'!C8<=0),'Cash with $2,000 founder salary'!C8<=0,IF('Cash with $2,000 founder salary'!C8="","",'Cash with $2,000 founder salary'!C8<=0))="",FALSE,IF(ISERROR('Cash with $2,000 founder salary'!C8<=0),'Cash with $2,000 founder salary'!C8<=0,IF('Cash with $2,000 founder salary'!C8="","",'Cash with $2,000 founder salary'!C8<=0))),0,IF(IF(IF(ISERROR('Cash with $2,000 founder salary'!C7>=0),'Cash with $2,000 founder salary'!C7>=0,IF('Cash with $2,000 founder salary'!C7="","",'Cash with $2,000 founder salary'!C7>=0))="",FALSE,IF(ISERROR('Cash with $2,000 founder salary'!C7>=0),'Cash with $2,000 founder salary'!C7>=0,IF('Cash with $2,000 founder salary'!C7="","",'Cash with $2,000 founder salary'!C7>=0))),"",'Cash with $2,000 founder salary'!C8/-'Cash with $2,000 founder salary'!C7)) -> 0 | D9: =IF(IF(IF(ISERROR('Cash with $2,000 founder salary'!D8<=0),'Cash with $2,000 founder salary'!D8<=0,IF('Cash with $2,000 founder salary'!D8="","",'Cash with $2,000 founder salary'!D8<=0))="",FALSE,IF(ISERROR('Cash with $2,000 founder salary'!D8<=0),'Cash with $2,000 founder salary'!D8<=0,IF('Cash with $2,000 founder salary'!D8="","",'Cash with $2,000 founder salary'!D8<=0))),0,IF(IF(IF(ISERROR('Cash with $2,000 founder salary'!D7>=0),'Cash with $2,000 founder salary'!D7>=0,IF('Cash with $2,000 founder salary'!D7="","",'Cash with $2,000 founder salary'!D7>=0))="",FALSE,IF(ISERROR('Cash with $2,000 founder salary'!D7>=0),'Cash with $2,000 founder salary'!D7>=0,IF('Cash with $2,000 founder salary'!D7="","",'Cash with $2,000 founder salary'!D7>=0))),"",'Cash with $2,000 founder salary'!D8/-'Cash with $2,000 founder salary'!D7)) -> 0 | E9: =IF(IF(IF(ISERROR('Cash with $2,000 founder salary'!E8<=0),'Cash with $2,000 founder salary'!E8<=0,IF('Cash with $2,000 founder salary'!E8="","",'Cash with $2,000 founder salary'!E8<=0))="",FALSE,IF(ISERROR('Cash with $2,000 founder salary'!E8<=0),'Cash with $2,000 founder salary'!E8<=0,IF('Cash with $2,000 founder salary'!E8="","",'Cash with $2,000 founder salary'!E8<=0))),0,IF(IF(IF(ISERROR('Cash with $2,000 founder salary'!E7>=0),'Cash with $2,000 founder salary'!E7>=0,IF('Cash with $2,000 founder salary'!E7="","",'Cash with $2,000 founder salary'!E7>=0))="",FALSE,IF(ISERROR('Cash with $2,000 founder salary'!E7>=0),'Cash with $2,000 founder salary'!E7>=0,IF('Cash with $2,000 founder salary'!E7="","",'Cash with $2,000 founder salary'!E7>=0))),"",'Cash with $2,000 founder salary'!E8/-'Cash with $2,000 founder salary'!E7)) -> 0 | F9: =IF(IF(IF(ISERROR('Cash with $2,000 founder salary'!F8<=0),'Cash with $2,000 founder salary'!F8<=0,IF('Cash with $2,000 founder salary'!F8="","",'Cash with $2,000 founder salary'!F8<=0))="",FALSE,IF(ISERROR('Cash with $2,000 founder salary'!F8<=0),'Cash with $2,000 founder salary'!F8<=0,IF('Cash with $2,000 founder salary'!F8="","",'Cash with $2,000 founder salary'!F8<=0))),0,IF(IF(IF(ISERROR('Cash with $2,000 founder salary'!F7>=0),'Cash with $2,000 founder salary'!F7>=0,IF('Cash with $2,000 founder salary'!F7="","",'Cash with $2,000 founder salary'!F7>=0))="",FALSE,IF(ISERROR('Cash with $2,000 founder salary'!F7>=0),'Cash with $2,000 founder salary'!F7>=0,IF('Cash with $2,000 founder salary'!F7="","",'Cash with $2,000 founder salary'!F7>=0))),"",'Cash with $2,000 founder salary'!F8/-'Cash with $2,000 founder salary'!F7)) -> 0 | G9: =IF(IF(IF(ISERROR('Cash with $2,000 founder salary'!G8<=0),'Cash with $2,000 founder salary'!G8<=0,IF('Cash with $2,000 founder salary'!G8="","",'Cash with $2,000 founder salary'!G8<=0))="",FALSE,IF(ISERROR('Cash with $2,000 founder salary'!G8<=0),'Cash with $2,000 founder salary'!G8<=0,IF('Cash with $2,000 founder salary'!G8="","",'Cash with $2,000 founder salary'!G8<=0))),0,IF(IF(IF(ISERROR('Cash with $2,000 founder salary'!G7>=0),'Cash with $2,000 founder salary'!G7>=0,IF('Cash with $2,000 founder salary'!G7="","",'Cash with $2,000 founder salary'!G7>=0))="",FALSE,IF(ISERROR('Cash with $2,000 founder salary'!G7>=0),'Cash with $2,000 founder salary'!G7>=0,IF('Cash with $2,000 founder salary'!G7="","",'Cash with $2,000 founder salary'!G7>=0))),"",'Cash with $2,000 founder salary'!G8/-'Cash with $2,000 founder salary'!G7)) -> 0 | H9: =IF(IF(IF(ISERROR('Cash with $2,000 founder salary'!H8<=0),'Cash with $2,000 founder salary'!H8<=0,IF('Cash with $2,000 founder salary'!H8="","",'Cash with $2,000 founder salary'!H8<=0))="",FALSE,IF(ISERROR('Cash with $2,000 founder salary'!H8<=0),'Cash with $2,000 founder salary'!H8<=0,IF('Cash with $2,000 founder salary'!H8="","",'Cash with $2,000 founder salary'!H8<=0))),0,IF(IF(IF(ISERROR('Cash with $2,000 founder salary'!H7>=0),'Cash with $2,000 founder salary'!H7>=0,IF('Cash with $2,000 founder salary'!H7="","",'Cash with $2,000 founder salary'!H7>=0))="",FALSE,IF(ISERROR('Cash with $2,000 founder salary'!H7>=0),'Cash with $2,000 founder salary'!H7>=0,IF('Cash with $2,000 founder salary'!H7="","",'Cash with $2,000 founder salary'!H7>=0))),"",'Cash with $2,000 founder salary'!H8/-'Cash with $2,000 founder salary'!H7)) -> 0 | I9: =IF(IF(IF(ISERROR('Cash with $2,000 founder salary'!I8<=0),'Cash with $2,000 founder salary'!I8<=0,IF('Cash with $2,000 founder salary'!I8="","",'Cash with $2,000 founder salary'!I8<=0))="",FALSE,IF(ISERROR('Cash with $2,000 founder salary'!I8<=0),'Cash with $2,000 founder salary'!I8<=0,IF('Cash with $2,000 founder salary'!I8="","",'Cash with $2,000 founder salary'!I8<=0))),0,IF(IF(IF(ISERROR('Cash with $2,000 founder salary'!I7>=0),'Cash with $2,000 founder salary'!I7>=0,IF('Cash with $2,000 founder salary'!I7="","",'Cash with $2,000 founder salary'!I7>=0))="",FALSE,IF(ISERROR('Cash with $2,000 founder salary'!I7>=0),'Cash with $2,000 founder salary'!I7>=0,IF('Cash with $2,000 founder salary'!I7="","",'Cash with $2,000 founder salary'!I7>=0))),"",'Cash with $2,000 founder salary'!I8/-'Cash with $2,000 founder salary'!I7)) -> 0 | ... Y9: =IF(IF(IF(ISERROR('Cash with $2,000 founder salary'!Y8<=0),'Cash with $2,000 founder salary'!Y8<=0,IF('Cash with $2,000 founder salary'!Y8="","",'Cash with $2,000 founder salary'!Y8<=0))="",FALSE,IF(ISERROR('Cash with $2,000 founder salary'!Y8<=0),'Cash with $2,000 founder salary'!Y8<=0,IF('Cash with $2,000 founder salary'!Y8="","",'Cash with $2,000 founder salary'!Y8<=0))),0,IF(IF(IF(ISERROR('Cash with $2,000 founder salary'!Y7>=0),'Cash with $2,000 founder salary'!Y7>=0,IF('Cash with $2,000 founder salary'!Y7="","",'Cash with $2,000 founder salary'!Y7>=0))="",FALSE,IF(ISERROR('Cash with $2,000 founder salary'!Y7>=0),'Cash with $2,000 founder salary'!Y7>=0,IF('Cash with $2,000 founder salary'!Y7="","",'Cash with $2,000 founder salary'!Y7>=0))),"",'Cash with $2,000 founder salary'!Y8/-'Cash with $2,000 founder salary'!Y7)) -> 0

Sheet Model inputs
A1: Model inputs
A2: Integration values are aggregated snapshots; raw source records are not included.
A4: Variables
A5: Variable / segment | B5: Value | C5: 2026-09 | D5: 2026-10 | E5: 2026-11 | F5: 2026-12 | G5: 2027-01 | H5: 2027-02 | I5: 2027-03 | J5: 2027-04 | K5: 2027-05 | L5: 2027-06 | M5: 2027-07 | N5: 2027-08 | O5: 2027-09 | P5: 2027-10 | Q5: 2027-11 | R5: 2027-12 | S5: 2028-01 | T5: 2028-02 | U5: 2028-03 | V5: 2028-04 | W5: 2028-05 | X5: 2028-06 | Y5: 2028-07 | Z5: 2028-08 | AA5: 2028-09 | AB5: 2026-08
A6: All-in cost per verified fix · Cash & runway | B6: =0.13 -> 0.13
A7: Cash balance | C7: =IF('Model inputs'!B32="","",'Model inputs'!B32) -> 3000 | D7: ='Model inputs'!C7+'Model inputs'!D19 -> 2830 | E7: ='Model inputs'!D7+'Model inputs'!E19 -> 2562.5 | F7: ='Model inputs'!E7+'Model inputs'!F19 -> 2542.35 | G7: ='Model inputs'!F7+'Model inputs'!G19 -> 2522.2 | H7: ='Model inputs'!G7+'Model inputs'!H19 -> 2502.05 | I7: ='Model inputs'!H7+'Model inputs'!I19 -> 2481.9 | J7: ='Model inputs'!I7+'Model inputs'!J19 -> 2461.75 | K7: ='Model inputs'!J7+'Model inputs'!K19 -> 2441.6 | ... AA7: ='Model inputs'!Z7+'Model inputs'!AA19 -> 2119.2
A8: Cash balance with salary | C8: =IF('Model inputs'!B32="","",'Model inputs'!B32) -> 3000 | D8: ='Model inputs'!C8+'Model inputs'!D20 -> 830 | E8: ='Model inputs'!D8+'Model inputs'!E20 -> -1437.5 | F8: ='Model inputs'!E8+'Model inputs'!F20 -> -3457.65 | G8: ='Model inputs'!F8+'Model inputs'!G20 -> -5477.8 | H8: ='Model inputs'!G8+'Model inputs'!H20 -> -7497.95 | I8: ='Model inputs'!H8+'Model inputs'!I20 -> -9518.1 | J8: ='Model inputs'!I8+'Model inputs'!J20 -> -11538.25 | K8: ='Model inputs'!J8+'Model inputs'!K20 -> -13558.4 | ... AA8: ='Model inputs'!Z8+'Model inputs'!AA20 -> -45880.8
A9: Cash collected from customers | C9: 0 | D9: ='Model inputs'!C22*(1-'Model inputs'!B21) -> 0 | E9: ='Model inputs'!D22*(1-'Model inputs'!B21) -> 0 | F9: ='Model inputs'!E22*(1-'Model inputs'!B21) -> 247.35 | G9: ='Model inputs'!F22*(1-'Model inputs'!B21) -> 247.35 | H9: ='Model inputs'!G22*(1-'Model inputs'!B21) -> 247.35 | I9: ='Model inputs'!H22*(1-'Model inputs'!B21) -> 247.35 | J9: ='Model inputs'!I22*(1-'Model inputs'!B21) -> 247.35 | K9: ='Model inputs'!J22*(1-'Model inputs'!B21) -> 247.35 | L9: ='Model inputs'!K22*(1-'Model inputs'!B21) -> 247.35 | M9: ='Model inputs'!L22*(1-'Model inputs'!B21) -> 247.35 | N9: ='Model inputs'!M22*(1-'Model inputs'!B21) -> 247.35 | O9: ='Model inputs'!N22*(1-'Model inputs'!B21) -> 247.35 | P9: ='Model inputs'!O22*(1-'Model inputs'!B21) -> 247.35 | Q9: ='Model inputs'!P22*(1-'Model inputs'!B21) -> 247.35 | R9: ='Model inputs'!Q22*(1-'Model inputs'!B21) -> 247.35 | S9: ='Model inputs'!R22*(1-'Model inputs'!B21) -> 247.35 | T9: ='Model inputs'!S22*(1-'Model inputs'!B21) -> 247.35 | U9: ='Model inputs'!T22*(1-'Model inputs'!B21) -> 247.35 | V9: ='Model inputs'!U22*(1-'Model inputs'!B21) -> 247.35 | W9: ='Model inputs'!V22*(1-'Model inputs'!B21) -> 247.35 | X9: ='Model inputs'!W22*(1-'Model inputs'!B21) -> 247.35 | Y9: ='Model inputs'!X22*(1-'Model inputs'!B21) -> 247.35 | Z9: ='Model inputs'!Y22*(1-'Model inputs'!B21) -> 247.35 | AA9: ='Model inputs'!Z22*(1-'Model inputs'!B21) -> 247.35
A10: Cost of revenue | D10: ='Model inputs'!D18+'Model inputs'!D30 -> 0 | E10: ='Model inputs'!E18+'Model inputs'!E30 -> 105.15 | F10: ='Model inputs'!F18+'Model inputs'!F30 -> 105.15 | G10: ='Model inputs'!G18+'Model inputs'!G30 -> 105.15 | H10: ='Model inputs'!H18+'Model inputs'!H30 -> 105.15 | I10: ='Model inputs'!I18+'Model inputs'!I30 -> 105.15 | J10: ='Model inputs'!J18+'Model inputs'!J30 -> 105.15 | K10: ='Model inputs'!K18+'Model inputs'!K30 -> 105.15 | ... AA10: ='Model inputs'!AA18+'Model inputs'!AA30 -> 105.15
A11: Fixed costs | C11: =SUM('Model inputs'!C12,'Model inputs'!C13,'Model inputs'!C14,'Model inputs'!C15) -> 0 | D11: =SUM('Model inputs'!D12,'Model inputs'!D13,'Model inputs'!D14,'Model inputs'!D15) -> 170 | E11: =SUM('Model inputs'!E12,'Model inputs'!E13,'Model inputs'!E14,'Model inputs'!E15) -> 170 | F11: =SUM('Model inputs'!F12,'Model inputs'!F13,'Model inputs'!F14,'Model inputs'!F15) -> 170 | G11: =SUM('Model inputs'!G12,'Model inputs'!G13,'Model inputs'!G14,'Model inputs'!G15) -> 170 | H11: =SUM('Model inputs'!H12,'Model inputs'!H13,'Model inputs'!H14,'Model inputs'!H15) -> 170 | I11: =SUM('Model inputs'!I12,'Model inputs'!I13,'Model inputs'!I14,'Model inputs'!I15) -> 170 | J11: =SUM('Model inputs'!J12,'Model inputs'!J13,'Model inputs'!J14,'Model inputs'!J15) -> 170 | ... AA11: =SUM('Model inputs'!AA12,'Model inputs'!AA13,'Model inputs'!AA14,'Model inputs'!AA15) -> 170
A12: Fixed costs > Accounting, legal & misc | C12: =0 -> 0 | D12: =IF('Model inputs'!B26="","",'Model inputs'!B26) -> 50 | E12: =IF('Model inputs'!B26="","",'Model inputs'!B26) -> 50 | F12: =IF('Model inputs'!B26="","",'Model inputs'!B26) -> 50 | G12: =IF('Model inputs'!B26="","",'Model inputs'!B26) -> 50 | H12: =IF('Model inputs'!B26="","",'Model inputs'!B26) -> 50 | I12: =IF('Model inputs'!B26="","",'Model inputs'!B26) -> 50 | J12: =IF('Model inputs'!B26="","",'Model inputs'!B26) -> 50 | K12: =IF('Model inputs'!B26="","",'Model inputs'!B26) -> 50 | L12: =IF('Model inputs'!B26="","",'Model inputs'!B26) -> 50 | M12: =IF('Model inputs'!B26="","",'Model inputs'!B26) -> 50 | N12: =IF('Model inputs'!B26="","",'Model inputs'!B26) -> 50 | O12: =IF('Model inputs'!B26="","",'Model inputs'!B26) -> 50 | P12: =IF('Model inputs'!B26="","",'Model inputs'!B26) -> 50 | Q12: =IF('Model inputs'!B26="","",'Model inputs'!B26) -> 50 | R12: =IF('Model inputs'!B26="","",'Model inputs'!B26) -> 50 | S12: =IF('Model inputs'!B26="","",'Model inputs'!B26) -> 50 | T12: =IF('Model inputs'!B26="","",'Model inputs'!B26) -> 50 | U12: =IF('Model inputs'!B26="","",'Model inputs'!B26) -> 50 | V12: =IF('Model inputs'!B26="","",'Model inputs'!B26) -> 50 | W12: =IF('Model inputs'!B26="","",'Model inputs'!B26) -> 50 | X12: =IF('Model inputs'!B26="","",'Model inputs'!B26) -> 50 | Y12: =IF('Model inputs'!B26="","",'Model inputs'!B26) -> 50 | Z12: =IF('Model inputs'!B26="","",'Model inputs'!B26) -> 50 | AA12: =IF('Model inputs'!B26="","",'Model inputs'!B26) -> 50
A13: Fixed costs > Hosting | C13: =0 -> 0 | D13: =IF('Model inputs'!B27="","",'Model inputs'!B27) -> 40 | E13: =IF('Model inputs'!B27="","",'Model inputs'!B27) -> 40 | F13: =IF('Model inputs'!B27="","",'Model inputs'!B27) -> 40 | G13: =IF('Model inputs'!B27="","",'Model inputs'!B27) -> 40 | H13: =IF('Model inputs'!B27="","",'Model inputs'!B27) -> 40 | I13: =IF('Model inputs'!B27="","",'Model inputs'!B27) -> 40 | J13: =IF('Model inputs'!B27="","",'Model inputs'!B27) -> 40 | K13: =IF('Model inputs'!B27="","",'Model inputs'!B27) -> 40 | L13: =IF('Model inputs'!B27="","",'Model inputs'!B27) -> 40 | M13: =IF('Model inputs'!B27="","",'Model inputs'!B27) -> 40 | N13: =IF('Model inputs'!B27="","",'Model inputs'!B27) -> 40 | O13: =IF('Model inputs'!B27="","",'Model inputs'!B27) -> 40 | P13: =IF('Model inputs'!B27="","",'Model inputs'!B27) -> 40 | Q13: =IF('Model inputs'!B27="","",'Model inputs'!B27) -> 40 | R13: =IF('Model inputs'!B27="","",'Model inputs'!B27) -> 40 | S13: =IF('Model inputs'!B27="","",'Model inputs'!B27) -> 40 | T13: =IF('Model inputs'!B27="","",'Model inputs'!B27) -> 40 | U13: =IF('Model inputs'!B27="","",'Model inputs'!B27) -> 40 | V13: =IF('Model inputs'!B27="","",'Model inputs'!B27) -> 40 | W13: =IF('Model inputs'!B27="","",'Model inputs'!B27) -> 40 | X13: =IF('Model inputs'!B27="","",'Model inputs'!B27) -> 40 | Y13: =IF('Model inputs'!B27="","",'Model inputs'!B27) -> 40 | Z13: =IF('Model inputs'!B27="","",'Model inputs'!B27) -> 40 | AA13: =IF('Model inputs'!B27="","",'Model inputs'!B27) -> 40
A14: Fixed costs > Observability | C14: =0 -> 0 | D14: =IF('Model inputs'!B28="","",'Model inputs'!B28) -> 50 | E14: =IF('Model inputs'!B28="","",'Model inputs'!B28) -> 50 | F14: =IF('Model inputs'!B28="","",'Model inputs'!B28) -> 50 | G14: =IF('Model inputs'!B28="","",'Model inputs'!B28) -> 50 | H14: =IF('Model inputs'!B28="","",'Model inputs'!B28) -> 50 | I14: =IF('Model inputs'!B28="","",'Model inputs'!B28) -> 50 | J14: =IF('Model inputs'!B28="","",'Model inputs'!B28) -> 50 | K14: =IF('Model inputs'!B28="","",'Model inputs'!B28) -> 50 | L14: =IF('Model inputs'!B28="","",'Model inputs'!B28) -> 50 | M14: =IF('Model inputs'!B28="","",'Model inputs'!B28) -> 50 | N14: =IF('Model inputs'!B28="","",'Model inputs'!B28) -> 50 | O14: =IF('Model inputs'!B28="","",'Model inputs'!B28) -> 50 | P14: =IF('Model inputs'!B28="","",'Model inputs'!B28) -> 50 | Q14: =IF('Model inputs'!B28="","",'Model inputs'!B28) -> 50 | R14: =IF('Model inputs'!B28="","",'Model inputs'!B28) -> 50 | S14: =IF('Model inputs'!B28="","",'Model inputs'!B28) -> 50 | T14: =IF('Model inputs'!B28="","",'Model inputs'!B28) -> 50 | U14: =IF('Model inputs'!B28="","",'Model inputs'!B28) -> 50 | V14: =IF('Model inputs'!B28="","",'Model inputs'!B28) -> 50 | W14: =IF('Model inputs'!B28="","",'Model inputs'!B28) -> 50 | X14: =IF('Model inputs'!B28="","",'Model inputs'!B28) -> 50 | Y14: =IF('Model inputs'!B28="","",'Model inputs'!B28) -> 50 | Z14: =IF('Model inputs'!B28="","",'Model inputs'!B28) -> 50 | AA14: =IF('Model inputs'!B28="","",'Model inputs'!B28) -> 50
A15: Fixed costs > Tooling & misc | C15: =0 -> 0 | D15: =IF('Model inputs'!B29="","",'Model inputs'!B29) -> 30 | E15: =IF('Model inputs'!B29="","",'Model inputs'!B29) -> 30 | F15: =IF('Model inputs'!B29="","",'Model inputs'!B29) -> 30 | G15: =IF('Model inputs'!B29="","",'Model inputs'!B29) -> 30 | H15: =IF('Model inputs'!B29="","",'Model inputs'!B29) -> 30 | I15: =IF('Model inputs'!B29="","",'Model inputs'!B29) -> 30 | J15: =IF('Model inputs'!B29="","",'Model inputs'!B29) -> 30 | K15: =IF('Model inputs'!B29="","",'Model inputs'!B29) -> 30 | L15: =IF('Model inputs'!B29="","",'Model inputs'!B29) -> 30 | M15: =IF('Model inputs'!B29="","",'Model inputs'!B29) -> 30 | N15: =IF('Model inputs'!B29="","",'Model inputs'!B29) -> 30 | O15: =IF('Model inputs'!B29="","",'Model inputs'!B29) -> 30 | P15: =IF('Model inputs'!B29="","",'Model inputs'!B29) -> 30 | Q15: =IF('Model inputs'!B29="","",'Model inputs'!B29) -> 30 | R15: =IF('Model inputs'!B29="","",'Model inputs'!B29) -> 30 | S15: =IF('Model inputs'!B29="","",'Model inputs'!B29) -> 30 | T15: =IF('Model inputs'!B29="","",'Model inputs'!B29) -> 30 | U15: =IF('Model inputs'!B29="","",'Model inputs'!B29) -> 30 | V15: =IF('Model inputs'!B29="","",'Model inputs'!B29) -> 30 | W15: =IF('Model inputs'!B29="","",'Model inputs'!B29) -> 30 | X15: =IF('Model inputs'!B29="","",'Model inputs'!B29) -> 30 | Y15: =IF('Model inputs'!B29="","",'Model inputs'!B29) -> 30 | Z15: =IF('Model inputs'!B29="","",'Model inputs'!B29) -> 30 | AA15: =IF('Model inputs'!B29="","",'Model inputs'!B29) -> 30
A16: Founder salary | C16: 0 | D16: =IF('Model inputs'!B17="","",'Model inputs'!B17) -> 2000 | E16: =IF('Model inputs'!B17="","",'Model inputs'!B17) -> 2000 | F16: =IF('Model inputs'!B17="","",'Model inputs'!B17) -> 2000 | G16: =IF('Model inputs'!B17="","",'Model inputs'!B17) -> 2000 | H16: =IF('Model inputs'!B17="","",'Model inputs'!B17) -> 2000 | I16: =IF('Model inputs'!B17="","",'Model inputs'!B17) -> 2000 | J16: =IF('Model inputs'!B17="","",'Model inputs'!B17) -> 2000 | K16: =IF('Model inputs'!B17="","",'Model inputs'!B17) -> 2000 | L16: =IF('Model inputs'!B17="","",'Model inputs'!B17) -> 2000 | M16: =IF('Model inputs'!B17="","",'Model inputs'!B17) -> 2000 | N16: =IF('Model inputs'!B17="","",'Model inputs'!B17) -> 2000 | O16: =IF('Model inputs'!B17="","",'Model inputs'!B17) -> 2000 | P16: =IF('Model inputs'!B17="","",'Model inputs'!B17) -> 2000 | Q16: =IF('Model inputs'!B17="","",'Model inputs'!B17) -> 2000 | R16: =IF('Model inputs'!B17="","",'Model inputs'!B17) -> 2000 | S16: =IF('Model inputs'!B17="","",'Model inputs'!B17) -> 2000 | T16: =IF('Model inputs'!B17="","",'Model inputs'!B17) -> 2000 | U16: =IF('Model inputs'!B17="","",'Model inputs'!B17) -> 2000 | V16: =IF('Model inputs'!B17="","",'Model inputs'!B17) -> 2000 | W16: =IF('Model inputs'!B17="","",'Model inputs'!B17) -> 2000 | X16: =IF('Model inputs'!B17="","",'Model inputs'!B17) -> 2000 | Y16: =IF('Model inputs'!B17="","",'Model inputs'!B17) -> 2000 | Z16: =IF('Model inputs'!B17="","",'Model inputs'!B17) -> 2000 | AA16: =IF('Model inputs'!B17="","",'Model inputs'!B17) -> 2000
A17: Founder salary (comparison) | B17: =2000 -> 2000
A18: Model usage cost | C18: 0 | D18: ='Model inputs'!D23*'Model inputs'!B6 -> 0 | E18: ='Model inputs'!E23*'Model inputs'!B6 -> 97.5 | F18: ='Model inputs'!F23*'Model inputs'!B6 -> 97.5 | G18: ='Model inputs'!G23*'Model inputs'!B6 -> 97.5 | H18: ='Model inputs'!H23*'Model inputs'!B6 -> 97.5 | I18: ='Model inputs'!I23*'Model inputs'!B6 -> 97.5 | J18: ='Model inputs'!J23*'Model inputs'!B6 -> 97.5 | K18: ='Model inputs'!K23*'Model inputs'!B6 -> 97.5 | L18: ='Model inputs'!L23*'Model inputs'!B6 -> 97.5 | M18: ='Model inputs'!M23*'Model inputs'!B6 -> 97.5 | N18: ='Model inputs'!N23*'Model inputs'!B6 -> 97.5 | O18: ='Model inputs'!O23*'Model inputs'!B6 -> 97.5 | P18: ='Model inputs'!P23*'Model inputs'!B6 -> 97.5 | Q18: ='Model inputs'!Q23*'Model inputs'!B6 -> 97.5 | R18: ='Model inputs'!R23*'Model inputs'!B6 -> 97.5 | S18: ='Model inputs'!S23*'Model inputs'!B6 -> 97.5 | T18: ='Model inputs'!T23*'Model inputs'!B6 -> 97.5 | U18: ='Model inputs'!U23*'Model inputs'!B6 -> 97.5 | V18: ='Model inputs'!V23*'Model inputs'!B6 -> 97.5 | W18: ='Model inputs'!W23*'Model inputs'!B6 -> 97.5 | X18: ='Model inputs'!X23*'Model inputs'!B6 -> 97.5 | Y18: ='Model inputs'!Y23*'Model inputs'!B6 -> 97.5 | Z18: ='Model inputs'!Z23*'Model inputs'!B6 -> 97.5 | AA18: ='Model inputs'!AA23*'Model inputs'!B6 -> 97.5
A19: Net cash flow | C19: 0 | D19: ='Model inputs'!D9-'Model inputs'!D18-'Model inputs'!D11 -> -170 | E19: ='Model inputs'!E9-'Model inputs'!E18-'Model inputs'!E11 -> -267.5 | F19: ='Model inputs'!F9-'Model inputs'!F18-'Model inputs'!F11 -> -20.15 | G19: ='Model inputs'!G9-'Model inputs'!G18-'Model inputs'!G11 -> -20.15 | H19: ='Model inputs'!H9-'Model inputs'!H18-'Model inputs'!H11 -> -20.15 | I19: ='Model inputs'!I9-'Model inputs'!I18-'Model inputs'!I11 -> -20.15 | J19: ='Model inputs'!J9-'Model inputs'!J18-'Model inputs'!J11 -> -20.15 | K19: ='Model inputs'!K9-'Model inputs'!K18-'Model inputs'!K11 -> -20.15 | ... AA19: ='Model inputs'!AA9-'Model inputs'!AA18-'Model inputs'!AA11 -> -20.15
A20: Net cash flow with salary | C20: 0 | D20: ='Model inputs'!D19-'Model inputs'!D16 -> -2170 | E20: ='Model inputs'!E19-'Model inputs'!E16 -> -2267.5 | F20: ='Model inputs'!F19-'Model inputs'!F16 -> -2020.15 | G20: ='Model inputs'!G19-'Model inputs'!G16 -> -2020.15 | H20: ='Model inputs'!H19-'Model inputs'!H16 -> -2020.15 | I20: ='Model inputs'!I19-'Model inputs'!I16 -> -2020.15 | J20: ='Model inputs'!J19-'Model inputs'!J16 -> -2020.15 | K20: ='Model inputs'!K19-'Model inputs'!K16 -> -2020.15 | ... AA20: ='Model inputs'!AA19-'Model inputs'!AA16 -> -2020.15
A21: Payment processing rate · Cash & runway | B21: =0.03 -> 0.03
A22: Revenue | C22: 0 | D22: ='Model inputs'!D23*'Model inputs'!B31 -> 0 | E22: ='Model inputs'!E23*'Model inputs'!B31 -> 255 | F22: ='Model inputs'!F23*'Model inputs'!B31 -> 255 | G22: ='Model inputs'!G23*'Model inputs'!B31 -> 255 | H22: ='Model inputs'!H23*'Model inputs'!B31 -> 255 | I22: ='Model inputs'!I23*'Model inputs'!B31 -> 255 | J22: ='Model inputs'!J23*'Model inputs'!B31 -> 255 | K22: ='Model inputs'!K23*'Model inputs'!B31 -> 255 | L22: ='Model inputs'!L23*'Model inputs'!B31 -> 255 | M22: ='Model inputs'!M23*'Model inputs'!B31 -> 255 | N22: ='Model inputs'!N23*'Model inputs'!B31 -> 255 | O22: ='Model inputs'!O23*'Model inputs'!B31 -> 255 | P22: ='Model inputs'!P23*'Model inputs'!B31 -> 255 | Q22: ='Model inputs'!Q23*'Model inputs'!B31 -> 255 | R22: ='Model inputs'!R23*'Model inputs'!B31 -> 255 | S22: ='Model inputs'!S23*'Model inputs'!B31 -> 255 | T22: ='Model inputs'!T23*'Model inputs'!B31 -> 255 | U22: ='Model inputs'!U23*'Model inputs'!B31 -> 255 | V22: ='Model inputs'!V23*'Model inputs'!B31 -> 255 | W22: ='Model inputs'!W23*'Model inputs'!B31 -> 255 | X22: ='Model inputs'!X23*'Model inputs'!B31 -> 255 | Y22: ='Model inputs'!Y23*'Model inputs'!B31 -> 255 | Z22: ='Model inputs'!Z23*'Model inputs'!B31 -> 255 | AA22: ='Model inputs'!AA23*'Model inputs'!B31 -> 255 | AB22: 0
A23: Verified fixes | C23: 0 | D23: ='Model inputs'!D24*'Model inputs'!B33 -> 0 | E23: ='Model inputs'!E24*'Model inputs'!B33 -> 750 | F23: ='Model inputs'!F24*'Model inputs'!B33 -> 750 | G23: ='Model inputs'!G24*'Model inputs'!B33 -> 750 | H23: ='Model inputs'!H24*'Model inputs'!B33 -> 750 | I23: ='Model inputs'!I24*'Model inputs'!B33 -> 750 | J23: ='Model inputs'!J24*'Model inputs'!B33 -> 750 | K23: ='Model inputs'!K24*'Model inputs'!B33 -> 750 | L23: ='Model inputs'!L24*'Model inputs'!B33 -> 750 | M23: ='Model inputs'!M24*'Model inputs'!B33 -> 750 | N23: ='Model inputs'!N24*'Model inputs'!B33 -> 750 | O23: ='Model inputs'!O24*'Model inputs'!B33 -> 750 | P23: ='Model inputs'!P24*'Model inputs'!B33 -> 750 | Q23: ='Model inputs'!Q24*'Model inputs'!B33 -> 750 | R23: ='Model inputs'!R24*'Model inputs'!B33 -> 750 | S23: ='Model inputs'!S24*'Model inputs'!B33 -> 750 | T23: ='Model inputs'!T24*'Model inputs'!B33 -> 750 | U23: ='Model inputs'!U24*'Model inputs'!B33 -> 750 | V23: ='Model inputs'!V24*'Model inputs'!B33 -> 750 | W23: ='Model inputs'!W24*'Model inputs'!B33 -> 750 | X23: ='Model inputs'!X24*'Model inputs'!B33 -> 750 | Y23: ='Model inputs'!Y24*'Model inputs'!B33 -> 750 | Z23: ='Model inputs'!Z24*'Model inputs'!B33 -> 750 | AA23: ='Model inputs'!AA24*'Model inputs'!B33 -> 750 | AB23: 0
A24: Jobs attempted · Cash & runway | C24: 0 | D24: =IF(IF(IF(ISERROR('Model inputs'!D37<1),'Model inputs'!D37<1,IF('Model inputs'!D37="","",'Model inputs'!D37<1))="",FALSE,IF(ISERROR('Model inputs'!D37<1),'Model inputs'!D37<1,IF('Model inputs'!D37="","",'Model inputs'!D37<1))),0,'Model inputs'!B35*IF(AND((1+'Model inputs'!B36)=0,(MIN('Model inputs'!D37,'Model inputs'!B34)-1)=0),SQRT(-1),(1+'Model inputs'!B36)^(MIN('Model inputs'!D37,'Model inputs'!B34)-1))*'Model inputs'!B38) -> 0 | E24: =IF(IF(IF(ISERROR('Model inputs'!E37<1),'Model inputs'!E37<1,IF('Model inputs'!E37="","",'Model inputs'!E37<1))="",FALSE,IF(ISERROR('Model inputs'!E37<1),'Model inputs'!E37<1,IF('Model inputs'!E37="","",'Model inputs'!E37<1))),0,'Model inputs'!B35*IF(AND((1+'Model inputs'!B36)=0,(MIN('Model inputs'!E37,'Model inputs'!B34)-1)=0),SQRT(-1),(1+'Model inputs'!B36)^(MIN('Model inputs'!E37,'Model inputs'!B34)-1))*'Model inputs'!B38) -> 1000 | F24: =IF(IF(IF(ISERROR('Model inputs'!F37<1),'Model inputs'!F37<1,IF('Model inputs'!F37="","",'Model inputs'!F37<1))="",FALSE,IF(ISERROR('Model inputs'!F37<1),'Model inputs'!F37<1,IF('Model inputs'!F37="","",'Model inputs'!F37<1))),0,'Model inputs'!B35*IF(AND((1+'Model inputs'!B36)=0,(MIN('Model inputs'!F37,'Model inputs'!B34)-1)=0),SQRT(-1),(1+'Model inputs'!B36)^(MIN('Model inputs'!F37,'Model inputs'!B34)-1))*'Model inputs'!B38) -> 1000 | G24: =IF(IF(IF(ISERROR('Model inputs'!G37<1),'Model inputs'!G37<1,IF('Model inputs'!G37="","",'Model inputs'!G37<1))="",FALSE,IF(ISERROR('Model inputs'!G37<1),'Model inputs'!G37<1,IF('Model inputs'!G37="","",'Model inputs'!G37<1))),0,'Model inputs'!B35*IF(AND((1+'Model inputs'!B36)=0,(MIN('Model inputs'!G37,'Model inputs'!B34)-1)=0),SQRT(-1),(1+'Model inputs'!B36)^(MIN('Model inputs'!G37,'Model inputs'!B34)-1))*'Model inputs'!B38) -> 1000 | H24: =IF(IF(IF(ISERROR('Model inputs'!H37<1),'Model inputs'!H37<1,IF('Model inputs'!H37="","",'Model inputs'!H37<1))="",FALSE,IF(ISERROR('Model inputs'!H37<1),'Model inputs'!H37<1,IF('Model inputs'!H37="","",'Model inputs'!H37<1))),0,'Model inputs'!B35*IF(AND((1+'Model inputs'!B36)=0,(MIN('Model inputs'!H37,'Model inputs'!B34)-1)=0),SQRT(-1),(1+'Model inputs'!B36)^(MIN('Model inputs'!H37,'Model inputs'!B34)-1))*'Model inputs'!B38) -> 1000 | I24: =IF(IF(IF(ISERROR('Model inputs'!I37<1),'Model inputs'!I37<1,IF('Model inputs'!I37="","",'Model inputs'!I37<1))="",FALSE,IF(ISERROR('Model inputs'!I37<1),'Model inputs'!I37<1,IF('Model inputs'!I37="","",'Model inputs'!I37<1))),0,'Model inputs'!B35*IF(AND((1+'Model inputs'!B36)=0,(MIN('Model inputs'!I37,'Model inputs'!B34)-1)=0),SQRT(-1),(1+'Model inputs'!B36)^(MIN('Model inputs'!I37,'Model inputs'!B34)-1))*'Model inputs'!B38) -> 1000 | J24: =IF(IF(IF(ISERROR('Model inputs'!J37<1),'Model inputs'!J37<1,IF('Model inputs'!J37="","",'Model inputs'!J37<1))="",FALSE,IF(ISERROR('Model inputs'!J37<1),'Model inputs'!J37<1,IF('Model inputs'!J37="","",'Model inputs'!J37<1))),0,'Model inputs'!B35*IF(AND((1+'Model inputs'!B36)=0,(MIN('Model inputs'!J37,'Model inputs'!B34)-1)=0),SQRT(-1),(1+'Model inputs'!B36)^(MIN('Model inputs'!J37,'Model inputs'!B34)-1))*'Model inputs'!B38) -> 1000 | K24: =IF(IF(IF(ISERROR('Model inputs'!K37<1),'Model inputs'!K37<1,IF('Model inputs'!K37="","",'Model inputs'!K37<1))="",FALSE,IF(ISERROR('Model inputs'!K37<1),'Model inputs'!K37<1,IF('Model inputs'!K37="","",'Model inputs'!K37<1))),0,'Model inputs'!B35*IF(AND((1+'Model inputs'!B36)=0,(MIN('Model inputs'!K37,'Model inputs'!B34)-1)=0),SQRT(-1),(1+'Model inputs'!B36)^(MIN('Model inputs'!K37,'Model inputs'!B34)-1))*'Model inputs'!B38) -> 1000 | L24: =IF(IF(IF(ISERROR('Model inputs'!L37<1),'Model inputs'!L37<1,IF('Model inputs'!L37="","",'Model inputs'!L37<1))="",FALSE,IF(ISERROR('Model inputs'!L37<1),'Model inputs'!L37<1,IF('Model inputs'!L37="","",'Model inputs'!L37<1))),0,'Model inputs'!B35*IF(AND((1+'Model inputs'!B36)=0,(MIN('Model inputs'!L37,'Model inputs'!B34)-1)=0),SQRT(-1),(1+'Model inputs'!B36)^(MIN('Model inputs'!L37,'Model inputs'!B34)-1))*'Model inputs'!B38) -> 1000 | M24: =IF(IF(IF(ISERROR('Model inputs'!M37<1),'Model inputs'!M37<1,IF('Model inputs'!M37="","",'Model inputs'!M37<1))="",FALSE,IF(ISERROR('Model inputs'!M37<1),'Model inputs'!M37<1,IF('Model inputs'!M37="","",'Model inputs'!M37<1))),0,'Model inputs'!B35*IF(AND((1+'Model inputs'!B36)=0,(MIN('Model inputs'!M37,'Model inputs'!B34)-1)=0),SQRT(-1),(1+'Model inputs'!B36)^(MIN('Model inputs'!M37,'Model inputs'!B34)-1))*'Model inputs'!B38) -> 1000 | N24: =IF(IF(IF(ISERROR('Model inputs'!N37<1),'Model inputs'!N37<1,IF('Model inputs'!N37="","",'Model inputs'!N37<1))="",FALSE,IF(ISERROR('Model inputs'!N37<1),'Model inputs'!N37<1,IF('Model inputs'!N37="","",'Model inputs'!N37<1))),0,'Model inputs'!B35*IF(AND((1+'Model inputs'!B36)=0,(MIN('Model inputs'!N37,'Model inputs'!B34)-1)=0),SQRT(-1),(1+'Model inputs'!B36)^(MIN('Model inputs'!N37,'Model inputs'!B34)-1))*'Model inputs'!B38) -> 1000 | O24: =IF(IF(IF(ISERROR('Model inputs'!O37<1),'Model inputs'!O37<1,IF('Model inputs'!O37="","",'Model inputs'!O37<1))="",FALSE,IF(ISERROR('Model inputs'!O37<1),'Model inputs'!O37<1,IF('Model inputs'!O37="","",'Model inputs'!O37<1))),0,'Model inputs'!B35*IF(AND((1+'Model inputs'!B36)=0,(MIN('Model inputs'!O37,'Model inputs'!B34)-1)=0),SQRT(-1),(1+'Model inputs'!B36)^(MIN('Model inputs'!O37,'Model inputs'!B34)-1))*'Model inputs'!B38) -> 1000 | P24: =IF(IF(IF(ISERROR('Model inputs'!P37<1),'Model inputs'!P37<1,IF('Model inputs'!P37="","",'Model inputs'!P37<1))="",FALSE,IF(ISERROR('Model inputs'!P37<1),'Model inputs'!P37<1,IF('Model inputs'!P37="","",'Model inputs'!P37<1))),0,'Model inputs'!B35*IF(AND((1+'Model inputs'!B36)=0,(MIN('Model inputs'!P37,'Model inputs'!B34)-1)=0),SQRT(-1),(1+'Model inputs'!B36)^(MIN('Model inputs'!P37,'Model inputs'!B34)-1))*'Model inputs'!B38) -> 1000 | Q24: =IF(IF(IF(ISERROR('Model inputs'!Q37<1),'Model inputs'!Q37<1,IF('Model inputs'!Q37="","",'Model inputs'!Q37<1))="",FALSE,IF(ISERROR('Model inputs'!Q37<1),'Model inputs'!Q37<1,IF('Model inputs'!Q37="","",'Model inputs'!Q37<1))),0,'Model inputs'!B35*IF(AND((1+'Model inputs'!B36)=0,(MIN('Model inputs'!Q37,'Model inputs'!B34)-1)=0),SQRT(-1),(1+'Model inputs'!B36)^(MIN('Model inputs'!Q37,'Model inputs'!B34)-1))*'Model inputs'!B38) -> 1000 | R24: =IF(IF(IF(ISERROR('Model inputs'!R37<1),'Model inputs'!R37<1,IF('Model inputs'!R37="","",'Model inputs'!R37<1))="",FALSE,IF(ISERROR('Model inputs'!R37<1),'Model inputs'!R37<1,IF('Model inputs'!R37="","",'Model inputs'!R37<1))),0,'Model inputs'!B35*IF(AND((1+'Model inputs'!B36)=0,(MIN('Model inputs'!R37,'Model inputs'!B34)-1)=0),SQRT(-1),(1+'Model inputs'!B36)^(MIN('Model inputs'!R37,'Model inputs'!B34)-1))*'Model inputs'!B38) -> 1000 | S24: =IF(IF(IF(ISERROR('Model inputs'!S37<1),'Model inputs'!S37<1,IF('Model inputs'!S37="","",'Model inputs'!S37<1))="",FALSE,IF(ISERROR('Model inputs'!S37<1),'Model inputs'!S37<1,IF('Model inputs'!S37="","",'Model inputs'!S37<1))),0,'Model inputs'!B35*IF(AND((1+'Model inputs'!B36)=0,(MIN('Model inputs'!S37,'Model inputs'!B34)-1)=0),SQRT(-1),(1+'Model inputs'!B36)^(MIN('Model inputs'!S37,'Model inputs'!B34)-1))*'Model inputs'!B38) -> 1000 | T24: =IF(IF(IF(ISERROR('Model inputs'!T37<1),'Model inputs'!T37<1,IF('Model inputs'!T37="","",'Model inputs'!T37<1))="",FALSE,IF(ISERROR('Model inputs'!T37<1),'Model inputs'!T37<1,IF('Model inputs'!T37="","",'Model inputs'!T37<1))),0,'Model inputs'!B35*IF(AND((1+'Model inputs'!B36)=0,(MIN('Model inputs'!T37,'Model inputs'!B34)-1)=0),SQRT(-1),(1+'Model inputs'!B36)^(MIN('Model inputs'!T37,'Model inputs'!B34)-1))*'Model inputs'!B38) -> 1000 | U24: =IF(IF(IF(ISERROR('Model inputs'!U37<1),'Model inputs'!U37<1,IF('Model inputs'!U37="","",'Model inputs'!U37<1))="",FALSE,IF(ISERROR('Model inputs'!U37<1),'Model inputs'!U37<1,IF('Model inputs'!U37="","",'Model inputs'!U37<1))),0,'Model inputs'!B35*IF(AND((1+'Model inputs'!B36)=0,(MIN('Model inputs'!U37,'Model inputs'!B34)-1)=0),SQRT(-1),(1+'Model inputs'!B36)^(MIN('Model inputs'!U37,'Model inputs'!B34)-1))*'Model inputs'!B38) -> 1000 | V24: =IF(IF(IF(ISERROR('Model inputs'!V37<1),'Model inputs'!V37<1,IF('Model inputs'!V37="","",'Model inputs'!V37<1))="",FALSE,IF(ISERROR('Model inputs'!V37<1),'Model inputs'!V37<1,IF('Model inputs'!V37="","",'Model inputs'!V37<1))),0,'Model inputs'!B35*IF(AND((1+'Model inputs'!B36)=0,(MIN('Model inputs'!V37,'Model inputs'!B34)-1)=0),SQRT(-1),(1+'Model inputs'!B36)^(MIN('Model inputs'!V37,'Model inputs'!B34)-1))*'Model inputs'!B38) -> 1000 | W24: =IF(IF(IF(ISERROR('Model inputs'!W37<1),'Model inputs'!W37<1,IF('Model inputs'!W37="","",'Model inputs'!W37<1))="",FALSE,IF(ISERROR('Model inputs'!W37<1),'Model inputs'!W37<1,IF('Model inputs'!W37="","",'Model inputs'!W37<1))),0,'Model inputs'!B35*IF(AND((1+'Model inputs'!B36)=0,(MIN('Model inputs'!W37,'Model inputs'!B34)-1)=0),SQRT(-1),(1+'Model inputs'!B36)^(MIN('Model inputs'!W37,'Model inputs'!B34)-1))*'Model inputs'!B38) -> 1000 | X24: =IF(IF(IF(ISERROR('Model inputs'!X37<1),'Model inputs'!X37<1,IF('Model inputs'!X37="","",'Model inputs'!X37<1))="",FALSE,IF(ISERROR('Model inputs'!X37<1),'Model inputs'!X37<1,IF('Model inputs'!X37="","",'Model inputs'!X37<1))),0,'Model inputs'!B35*IF(AND((1+'Model inputs'!B36)=0,(MIN('Model inputs'!X37,'Model inputs'!B34)-1)=0),SQRT(-1),(1+'Model inputs'!B36)^(MIN('Model inputs'!X37,'Model inputs'!B34)-1))*'Model inputs'!B38) -> 1000 | Y24: =IF(IF(IF(ISERROR('Model inputs'!Y37<1),'Model inputs'!Y37<1,IF('Model inputs'!Y37="","",'Model inputs'!Y37<1))="",FALSE,IF(ISERROR('Model inputs'!Y37<1),'Model inputs'!Y37<1,IF('Model inputs'!Y37="","",'Model inputs'!Y37<1))),0,'Model inputs'!B35*IF(AND((1+'Model inputs'!B36)=0,(MIN('Model inputs'!Y37,'Model inputs'!B34)-1)=0),SQRT(-1),(1+'Model inputs'!B36)^(MIN('Model inputs'!Y37,'Model inputs'!B34)-1))*'Model inputs'!B38) -> 1000 | Z24: =IF(IF(IF(ISERROR('Model inputs'!Z37<1),'Model inputs'!Z37<1,IF('Model inputs'!Z37="","",'Model inputs'!Z37<1))="",FALSE,IF(ISERROR('Model inputs'!Z37<1),'Model inputs'!Z37<1,IF('Model inputs'!Z37="","",'Model inputs'!Z37<1))),0,'Model inputs'!B35*IF(AND((1+'Model inputs'!B36)=0,(MIN('Model inputs'!Z37,'Model inputs'!B34)-1)=0),SQRT(-1),(1+'Model inputs'!B36)^(MIN('Model inputs'!Z37,'Model inputs'!B34)-1))*'Model inputs'!B38) -> 1000 | AA24: =IF(IF(IF(ISERROR('Model inputs'!AA37<1),'Model inputs'!AA37<1,IF('Model inputs'!AA37="","",'Model inputs'!AA37<1))="",FALSE,IF(ISERROR('Model inputs'!AA37<1),'Model inputs'!AA37<1,IF('Model inputs'!AA37="","",'Model inputs'!AA37<1))),0,'Model inputs'!B35*IF(AND((1+'Model inputs'!B36)=0,(MIN('Model inputs'!AA37,'Model inputs'!B34)-1)=0),SQRT(-1),(1+'Model inputs'!B36)^(MIN('Model inputs'!AA37,'Model inputs'!B34)-1))*'Model inputs'!B38) -> 1000 | AB24: 0
A25: Monthly fixed cost | B25: 0
A26: Monthly fixed cost > Accounting, legal & misc | B26: =50 -> 50
A27: Monthly fixed cost > Hosting | B27: =40 -> 40
A28: Monthly fixed cost > Observability | B28: =50 -> 50
A29: Monthly fixed cost > Tooling & misc | B29: =30 -> 30
A30: Payment processing | D30: ='Model inputs'!D22*'Model inputs'!B21 -> 0 | E30: ='Model inputs'!E22*'Model inputs'!B21 -> 7.65 | F30: ='Model inputs'!F22*'Model inputs'!B21 -> 7.65 | G30: ='Model inputs'!G22*'Model inputs'!B21 -> 7.65 | H30: ='Model inputs'!H22*'Model inputs'!B21 -> 7.65 | I30: ='Model inputs'!I22*'Model inputs'!B21 -> 7.65 | J30: ='Model inputs'!J22*'Model inputs'!B21 -> 7.65 | K30: ='Model inputs'!K22*'Model inputs'!B21 -> 7.65 | L30: ='Model inputs'!L22*'Model inputs'!B21 -> 7.65 | M30: ='Model inputs'!M22*'Model inputs'!B21 -> 7.65 | N30: ='Model inputs'!N22*'Model inputs'!B21 -> 7.65 | O30: ='Model inputs'!O22*'Model inputs'!B21 -> 7.65 | P30: ='Model inputs'!P22*'Model inputs'!B21 -> 7.65 | Q30: ='Model inputs'!Q22*'Model inputs'!B21 -> 7.65 | R30: ='Model inputs'!R22*'Model inputs'!B21 -> 7.65 | S30: ='Model inputs'!S22*'Model inputs'!B21 -> 7.65 | T30: ='Model inputs'!T22*'Model inputs'!B21 -> 7.65 | U30: ='Model inputs'!U22*'Model inputs'!B21 -> 7.65 | V30: ='Model inputs'!V22*'Model inputs'!B21 -> 7.65 | W30: ='Model inputs'!W22*'Model inputs'!B21 -> 7.65 | X30: ='Model inputs'!X22*'Model inputs'!B21 -> 7.65 | Y30: ='Model inputs'!Y22*'Model inputs'!B21 -> 7.65 | Z30: ='Model inputs'!Z22*'Model inputs'!B21 -> 7.65 | AA30: ='Model inputs'!AA22*'Model inputs'!B21 -> 7.65
A31: Price per verified fix · Revenue | B31: =0.34 -> 0.34
A32: Starting cash | B32: =3000 -> 3000
A33: Verification rate · Verified fixes | B33: =0.75 -> 0.75
A34: Growth months · Jobs attempted · Cash & runway | B34: =12 -> 12
A35: Launch month jobs · Jobs attempted · Cash & runway | B35: =1000 -> 1000
A36: Monthly job growth · Jobs attempted · Cash & runway | B36: =0 -> 0
