Workbook

Sheet Scenario comparison by quarter
A1: Scenario comparison by quarter
A2: Scenarios · Main Scenario
A4: Variable / dimension | B4: 2026-10 | C4: 2026-10 > Base · $0.60 | D4: 2026-10 > Growth · $0.34 | E4: 2026-10 > Growth · $0.60 | F4: 2027-01 | G4: 2027-01 > Base · $0.60 | H4: 2027-01 > Growth · $0.34 | I4: 2027-01 > Growth · $0.60 | J4: 2027-04 | K4: 2027-04 > Base · $0.60 | L4: 2027-04 > Growth · $0.34 | M4: 2027-04 > Growth · $0.60 | N4: 2027-07 | O4: 2027-07 > Base · $0.60 | P4: 2027-07 > Growth · $0.34 | Q4: 2027-07 > Growth · $0.60 | R4: 2027-10 | S4: 2027-10 > Base · $0.60 | T4: 2027-10 > Growth · $0.34 | U4: 2027-10 > Growth · $0.60 | V4: 2028-01 | W4: 2028-01 > Base · $0.60 | X4: 2028-01 > Growth · $0.34 | Y4: 2028-01 > Growth · $0.60 | Z4: 2028-04 | AA4: 2028-04 > Base · $0.60 | AB4: 2028-04 > Growth · $0.34 | AC4: 2028-04 > Growth · $0.60 | AD4: 2028-07 | AE4: 2028-07 > Base · $0.60 | AF4: 2028-07 > Growth · $0.34 | AG4: 2028-07 > Growth · $0.60
A5: Jobs attempted | B5: =SUM('Model inputs'!K18,'Model inputs'!L18,'Model inputs'!M18) -> 2000 | C5: =SUM('Model inputs'!K20,'Model inputs'!L20,'Model inputs'!M20) -> 1700 | D5: =SUM('Model inputs'!K21,'Model inputs'!L21,'Model inputs'!M21) -> 2250 | E5: =SUM('Model inputs'!K19,'Model inputs'!L19,'Model inputs'!M19) -> 1912.5 | F5: =SUM('Model inputs'!N18,'Model inputs'!O18,'Model inputs'!P18) -> 3000 | G5: =SUM('Model inputs'!N20,'Model inputs'!O20,'Model inputs'!P20) -> 2550 | H5: =SUM('Model inputs'!N21,'Model inputs'!O21,'Model inputs'!P21) -> 5957.0312 | I5: =SUM('Model inputs'!N19,'Model inputs'!O19,'Model inputs'!P19) -> 5063.4766 | J5: =SUM('Model inputs'!Q18,'Model inputs'!R18,'Model inputs'!S18) -> 3000 | K5: =SUM('Model inputs'!Q20,'Model inputs'!R20,'Model inputs'!S20) -> 2550 | L5: =SUM('Model inputs'!Q21,'Model inputs'!R21,'Model inputs'!S21) -> 11634.827 | M5: =SUM('Model inputs'!Q19,'Model inputs'!R19,'Model inputs'!S19) -> 9889.6027 | N5: =SUM('Model inputs'!T18,'Model inputs'!U18,'Model inputs'!V18) -> 3000 | O5: =SUM('Model inputs'!T20,'Model inputs'!U20,'Model inputs'!V20) -> 2550 | P5: =SUM('Model inputs'!T21,'Model inputs'!U21,'Model inputs'!V21) -> 22724.271 | Q5: =SUM('Model inputs'!T19,'Model inputs'!U19,'Model inputs'!V19) -> 19315.63 | R5: =SUM('Model inputs'!W18,'Model inputs'!X18,'Model inputs'!Y18) -> 3000 | S5: =SUM('Model inputs'!W20,'Model inputs'!X20,'Model inputs'!Y20) -> 2550 | T5: =SUM('Model inputs'!W21,'Model inputs'!X21,'Model inputs'!Y21) -> 34924.597 | U5: =SUM('Model inputs'!W19,'Model inputs'!X19,'Model inputs'!Y19) -> 29685.907 | V5: =SUM('Model inputs'!Z18,'Model inputs'!AA18,'Model inputs'!AB18) -> 3000 | W5: =SUM('Model inputs'!Z20,'Model inputs'!AA20,'Model inputs'!AB20) -> 2550 | X5: =SUM('Model inputs'!Z21,'Model inputs'!AA21,'Model inputs'!AB21) -> 34924.597 | Y5: =SUM('Model inputs'!Z19,'Model inputs'!AA19,'Model inputs'!AB19) -> 29685.907 | Z5: =SUM('Model inputs'!AC18,'Model inputs'!AD18,'Model inputs'!AE18) -> 3000 | AA5: =SUM('Model inputs'!AC20,'Model inputs'!AD20,'Model inputs'!AE20) -> 2550 | AB5: =SUM('Model inputs'!AC21,'Model inputs'!AD21,'Model inputs'!AE21) -> 34924.597 | AC5: =SUM('Model inputs'!AC19,'Model inputs'!AD19,'Model inputs'!AE19) -> 29685.907 | AD5: =SUM('Model inputs'!AF18,'Model inputs'!AG18,'Model inputs'!AH18) -> 3000 | AE5: =SUM('Model inputs'!AF20,'Model inputs'!AG20,'Model inputs'!AH20) -> 2550 | AF5: =SUM('Model inputs'!AF21,'Model inputs'!AG21,'Model inputs'!AH21) -> 34924.597 | AG5: =SUM('Model inputs'!AF19,'Model inputs'!AG19,'Model inputs'!AH19) -> 29685.907
A6: Revenue | B6: =SUM('Model inputs'!K30,'Model inputs'!L30,'Model inputs'!M30) -> 510 | C6: =SUM('Model inputs'!K32,'Model inputs'!L32,'Model inputs'!M32) -> 765 | D6: =SUM('Model inputs'!K33,'Model inputs'!L33,'Model inputs'!M33) -> 573.75 | E6: =SUM('Model inputs'!K31,'Model inputs'!L31,'Model inputs'!M31) -> 860.625 | F6: =SUM('Model inputs'!N30,'Model inputs'!O30,'Model inputs'!P30) -> 765 | G6: =SUM('Model inputs'!N32,'Model inputs'!O32,'Model inputs'!P32) -> 1147.5 | H6: =SUM('Model inputs'!N33,'Model inputs'!O33,'Model inputs'!P33) -> 1519.043 | I6: =SUM('Model inputs'!N31,'Model inputs'!O31,'Model inputs'!P31) -> 2278.5645 | J6: =SUM('Model inputs'!Q30,'Model inputs'!R30,'Model inputs'!S30) -> 765 | K6: =SUM('Model inputs'!Q32,'Model inputs'!R32,'Model inputs'!S32) -> 1147.5 | L6: =SUM('Model inputs'!Q33,'Model inputs'!R33,'Model inputs'!S33) -> 2966.8808 | M6: =SUM('Model inputs'!Q31,'Model inputs'!R31,'Model inputs'!S31) -> 4450.3212 | N6: =SUM('Model inputs'!T30,'Model inputs'!U30,'Model inputs'!V30) -> 765 | O6: =SUM('Model inputs'!T32,'Model inputs'!U32,'Model inputs'!V32) -> 1147.5 | P6: =SUM('Model inputs'!T33,'Model inputs'!U33,'Model inputs'!V33) -> 5794.6891 | Q6: =SUM('Model inputs'!T31,'Model inputs'!U31,'Model inputs'!V31) -> 8692.0336 | R6: =SUM('Model inputs'!W30,'Model inputs'!X30,'Model inputs'!Y30) -> 765 | S6: =SUM('Model inputs'!W32,'Model inputs'!X32,'Model inputs'!Y32) -> 1147.5 | T6: =SUM('Model inputs'!W33,'Model inputs'!X33,'Model inputs'!Y33) -> 8905.7721 | U6: =SUM('Model inputs'!W31,'Model inputs'!X31,'Model inputs'!Y31) -> 13358.658 | V6: =SUM('Model inputs'!Z30,'Model inputs'!AA30,'Model inputs'!AB30) -> 765 | W6: =SUM('Model inputs'!Z32,'Model inputs'!AA32,'Model inputs'!AB32) -> 1147.5 | X6: =SUM('Model inputs'!Z33,'Model inputs'!AA33,'Model inputs'!AB33) -> 8905.7721 | Y6: =SUM('Model inputs'!Z31,'Model inputs'!AA31,'Model inputs'!AB31) -> 13358.658 | Z6: =SUM('Model inputs'!AC30,'Model inputs'!AD30,'Model inputs'!AE30) -> 765 | AA6: =SUM('Model inputs'!AC32,'Model inputs'!AD32,'Model inputs'!AE32) -> 1147.5 | AB6: =SUM('Model inputs'!AC33,'Model inputs'!AD33,'Model inputs'!AE33) -> 8905.7721 | AC6: =SUM('Model inputs'!AC31,'Model inputs'!AD31,'Model inputs'!AE31) -> 13358.658 | AD6: =SUM('Model inputs'!AF30,'Model inputs'!AG30,'Model inputs'!AH30) -> 765 | AE6: =SUM('Model inputs'!AF32,'Model inputs'!AG32,'Model inputs'!AH32) -> 1147.5 | AF6: =SUM('Model inputs'!AF33,'Model inputs'!AG33,'Model inputs'!AH33) -> 8905.7721 | AG6: =SUM('Model inputs'!AF31,'Model inputs'!AG31,'Model inputs'!AH31) -> 13358.658
A7: Gross profit | B7: =SUM('Model inputs'!K14,'Model inputs'!L14,'Model inputs'!M14) -> 299.7 | C7: =SUM('Model inputs'!K16,'Model inputs'!L16,'Model inputs'!M16) -> 576.3 | D7: =SUM('Model inputs'!K17,'Model inputs'!L17,'Model inputs'!M17) -> 337.1625 | E7: =SUM('Model inputs'!K15,'Model inputs'!L15,'Model inputs'!M15) -> 648.3375 | F7: =SUM('Model inputs'!N14,'Model inputs'!O14,'Model inputs'!P14) -> 449.55 | G7: =SUM('Model inputs'!N16,'Model inputs'!O16,'Model inputs'!P16) -> 864.45 | H7: =SUM('Model inputs'!N17,'Model inputs'!O17,'Model inputs'!P17) -> 892.66113 | I7: =SUM('Model inputs'!N15,'Model inputs'!O15,'Model inputs'!P15) -> 1716.5186 | J7: =SUM('Model inputs'!Q14,'Model inputs'!R14,'Model inputs'!S14) -> 449.55 | K7: =SUM('Model inputs'!Q16,'Model inputs'!R16,'Model inputs'!S16) -> 864.45 | L7: =SUM('Model inputs'!Q17,'Model inputs'!R17,'Model inputs'!S17) -> 1743.4788 | M7: =SUM('Model inputs'!Q15,'Model inputs'!R15,'Model inputs'!S15) -> 3352.5753 | N7: =SUM('Model inputs'!T14,'Model inputs'!U14,'Model inputs'!V14) -> 449.55 | O7: =SUM('Model inputs'!T16,'Model inputs'!U16,'Model inputs'!V16) -> 864.45 | P7: =SUM('Model inputs'!T17,'Model inputs'!U17,'Model inputs'!V17) -> 3405.232 | Q7: =SUM('Model inputs'!T15,'Model inputs'!U15,'Model inputs'!V15) -> 6547.9986 | R7: =SUM('Model inputs'!W14,'Model inputs'!X14,'Model inputs'!Y14) -> 449.55 | S7: =SUM('Model inputs'!W16,'Model inputs'!X16,'Model inputs'!Y16) -> 864.45 | T7: =SUM('Model inputs'!W17,'Model inputs'!X17,'Model inputs'!Y17) -> 5233.4508 | U7: =SUM('Model inputs'!W15,'Model inputs'!X15,'Model inputs'!Y15) -> 10063.522 | V7: =SUM('Model inputs'!Z14,'Model inputs'!AA14,'Model inputs'!AB14) -> 449.55 | W7: =SUM('Model inputs'!Z16,'Model inputs'!AA16,'Model inputs'!AB16) -> 864.45 | X7: =SUM('Model inputs'!Z17,'Model inputs'!AA17,'Model inputs'!AB17) -> 5233.4508 | Y7: =SUM('Model inputs'!Z15,'Model inputs'!AA15,'Model inputs'!AB15) -> 10063.522 | Z7: =SUM('Model inputs'!AC14,'Model inputs'!AD14,'Model inputs'!AE14) -> 449.55 | AA7: =SUM('Model inputs'!AC16,'Model inputs'!AD16,'Model inputs'!AE16) -> 864.45 | AB7: =SUM('Model inputs'!AC17,'Model inputs'!AD17,'Model inputs'!AE17) -> 5233.4508 | AC7: =SUM('Model inputs'!AC15,'Model inputs'!AD15,'Model inputs'!AE15) -> 10063.522 | AD7: =SUM('Model inputs'!AF14,'Model inputs'!AG14,'Model inputs'!AH14) -> 449.55 | AE7: =SUM('Model inputs'!AF16,'Model inputs'!AG16,'Model inputs'!AH16) -> 864.45 | AF7: =SUM('Model inputs'!AF17,'Model inputs'!AG17,'Model inputs'!AH17) -> 5233.4508 | AG7: =SUM('Model inputs'!AF15,'Model inputs'!AG15,'Model inputs'!AH15) -> 10063.522
A8: Operating profit | B8: =SUM('Model inputs'!K26,'Model inputs'!L26,'Model inputs'!M26) -> -210.3 | C8: =SUM('Model inputs'!K28,'Model inputs'!L28,'Model inputs'!M28) -> 66.3 | D8: =SUM('Model inputs'!K29,'Model inputs'!L29,'Model inputs'!M29) -> -172.8375 | E8: =SUM('Model inputs'!K27,'Model inputs'!L27,'Model inputs'!M27) -> 138.3375 | F8: =SUM('Model inputs'!N26,'Model inputs'!O26,'Model inputs'!P26) -> -60.45 | G8: =SUM('Model inputs'!N28,'Model inputs'!O28,'Model inputs'!P28) -> 354.45 | H8: =SUM('Model inputs'!N29,'Model inputs'!O29,'Model inputs'!P29) -> 382.66113 | I8: =SUM('Model inputs'!N27,'Model inputs'!O27,'Model inputs'!P27) -> 1206.5186 | J8: =SUM('Model inputs'!Q26,'Model inputs'!R26,'Model inputs'!S26) -> -60.45 | K8: =SUM('Model inputs'!Q28,'Model inputs'!R28,'Model inputs'!S28) -> 354.45 | L8: =SUM('Model inputs'!Q29,'Model inputs'!R29,'Model inputs'!S29) -> 1233.4788 | M8: =SUM('Model inputs'!Q27,'Model inputs'!R27,'Model inputs'!S27) -> 2842.5753 | N8: =SUM('Model inputs'!T26,'Model inputs'!U26,'Model inputs'!V26) -> -60.45 | O8: =SUM('Model inputs'!T28,'Model inputs'!U28,'Model inputs'!V28) -> 354.45 | P8: =SUM('Model inputs'!T29,'Model inputs'!U29,'Model inputs'!V29) -> 2895.232 | Q8: =SUM('Model inputs'!T27,'Model inputs'!U27,'Model inputs'!V27) -> 6037.9986 | R8: =SUM('Model inputs'!W26,'Model inputs'!X26,'Model inputs'!Y26) -> -60.45 | S8: =SUM('Model inputs'!W28,'Model inputs'!X28,'Model inputs'!Y28) -> 354.45 | T8: =SUM('Model inputs'!W29,'Model inputs'!X29,'Model inputs'!Y29) -> 4723.4508 | U8: =SUM('Model inputs'!W27,'Model inputs'!X27,'Model inputs'!Y27) -> 9553.5225 | V8: =SUM('Model inputs'!Z26,'Model inputs'!AA26,'Model inputs'!AB26) -> -60.45 | W8: =SUM('Model inputs'!Z28,'Model inputs'!AA28,'Model inputs'!AB28) -> 354.45 | X8: =SUM('Model inputs'!Z29,'Model inputs'!AA29,'Model inputs'!AB29) -> 4723.4508 | Y8: =SUM('Model inputs'!Z27,'Model inputs'!AA27,'Model inputs'!AB27) -> 9553.5225 | Z8: =SUM('Model inputs'!AC26,'Model inputs'!AD26,'Model inputs'!AE26) -> -60.45 | AA8: =SUM('Model inputs'!AC28,'Model inputs'!AD28,'Model inputs'!AE28) -> 354.45 | AB8: =SUM('Model inputs'!AC29,'Model inputs'!AD29,'Model inputs'!AE29) -> 4723.4508 | AC8: =SUM('Model inputs'!AC27,'Model inputs'!AD27,'Model inputs'!AE27) -> 9553.5225 | AD8: =SUM('Model inputs'!AF26,'Model inputs'!AG26,'Model inputs'!AH26) -> -60.45 | AE8: =SUM('Model inputs'!AF28,'Model inputs'!AG28,'Model inputs'!AH28) -> 354.45 | AF8: =SUM('Model inputs'!AF29,'Model inputs'!AG29,'Model inputs'!AH29) -> 4723.4508 | AG8: =SUM('Model inputs'!AF27,'Model inputs'!AG27,'Model inputs'!AH27) -> 9553.5225
A9: Net cash flow | B9: =SUM('Model inputs'!K22,'Model inputs'!L22,'Model inputs'!M22) -> -457.65 | C9: =SUM('Model inputs'!K24,'Model inputs'!L24,'Model inputs'!M24) -> -304.725 | D9: =SUM('Model inputs'!K25,'Model inputs'!L25,'Model inputs'!M25) -> -482.025 | E9: =SUM('Model inputs'!K23,'Model inputs'!L23,'Model inputs'!M23) -> -325.44375 | F9: =SUM('Model inputs'!N22,'Model inputs'!O22,'Model inputs'!P22) -> -60.45 | G9: =SUM('Model inputs'!N24,'Model inputs'!O24,'Model inputs'!P24) -> 354.45 | H9: =SUM('Model inputs'!N25,'Model inputs'!O25,'Model inputs'!P25) -> 87.966797 | I9: =SUM('Model inputs'!N23,'Model inputs'!O23,'Model inputs'!P23) -> 764.47705 | J9: =SUM('Model inputs'!Q22,'Model inputs'!R22,'Model inputs'!S22) -> -60.45 | K9: =SUM('Model inputs'!Q24,'Model inputs'!R24,'Model inputs'!S24) -> 354.45 | L9: =SUM('Model inputs'!Q25,'Model inputs'!R25,'Model inputs'!S25) -> 657.9039 | M9: =SUM('Model inputs'!Q23,'Model inputs'!R23,'Model inputs'!S23) -> 1979.213 | N9: =SUM('Model inputs'!T22,'Model inputs'!U22,'Model inputs'!V22) -> -60.45 | O9: =SUM('Model inputs'!T24,'Model inputs'!U24,'Model inputs'!V24) -> 354.45 | P9: =SUM('Model inputs'!T25,'Model inputs'!U25,'Model inputs'!V25) -> 1771.0623 | Q9: =SUM('Model inputs'!T23,'Model inputs'!U23,'Model inputs'!V23) -> 4351.7441 | R9: =SUM('Model inputs'!W22,'Model inputs'!X22,'Model inputs'!Y22) -> -60.45 | S9: =SUM('Model inputs'!W24,'Model inputs'!X24,'Model inputs'!Y24) -> 354.45 | T9: =SUM('Model inputs'!W25,'Model inputs'!X25,'Model inputs'!Y25) -> 4147.5442 | U9: =SUM('Model inputs'!W23,'Model inputs'!X23,'Model inputs'!Y23) -> 8689.6626 | V9: =SUM('Model inputs'!Z22,'Model inputs'!AA22,'Model inputs'!AB22) -> -60.45 | W9: =SUM('Model inputs'!Z24,'Model inputs'!AA24,'Model inputs'!AB24) -> 354.45 | X9: =SUM('Model inputs'!Z25,'Model inputs'!AA25,'Model inputs'!AB25) -> 4723.4508 | Y9: =SUM('Model inputs'!Z23,'Model inputs'!AA23,'Model inputs'!AB23) -> 9553.5225 | Z9: =SUM('Model inputs'!AC22,'Model inputs'!AD22,'Model inputs'!AE22) -> -60.45 | AA9: =SUM('Model inputs'!AC24,'Model inputs'!AD24,'Model inputs'!AE24) -> 354.45 | AB9: =SUM('Model inputs'!AC25,'Model inputs'!AD25,'Model inputs'!AE25) -> 4723.4508 | AC9: =SUM('Model inputs'!AC23,'Model inputs'!AD23,'Model inputs'!AE23) -> 9553.5225 | AD9: =SUM('Model inputs'!AF22,'Model inputs'!AG22,'Model inputs'!AH22) -> -60.45 | AE9: =SUM('Model inputs'!AF24,'Model inputs'!AG24,'Model inputs'!AH24) -> 354.45 | AF9: =SUM('Model inputs'!AF25,'Model inputs'!AG25,'Model inputs'!AH25) -> 4723.4508 | AG9: =SUM('Model inputs'!AF23,'Model inputs'!AG23,'Model inputs'!AH23) -> 9553.5225
A10: Cash balance | B10: =IF('Model inputs'!M6="","",'Model inputs'!M6) -> 2542.35 | C10: =IF('Model inputs'!M8="","",'Model inputs'!M8) -> 2695.275 | D10: =IF('Model inputs'!M9="","",'Model inputs'!M9) -> 2517.975 | E10: =IF('Model inputs'!M7="","",'Model inputs'!M7) -> 2674.5563 | F10: =IF('Model inputs'!P6="","",'Model inputs'!P6) -> 2481.9 | G10: =IF('Model inputs'!P8="","",'Model inputs'!P8) -> 3049.725 | H10: =IF('Model inputs'!P9="","",'Model inputs'!P9) -> 2605.9418 | I10: =IF('Model inputs'!P7="","",'Model inputs'!P7) -> 3439.0333 | J10: =IF('Model inputs'!S6="","",'Model inputs'!S6) -> 2421.45 | K10: =IF('Model inputs'!S8="","",'Model inputs'!S8) -> 3404.175 | L10: =IF('Model inputs'!S9="","",'Model inputs'!S9) -> 3263.8457 | M10: =IF('Model inputs'!S7="","",'Model inputs'!S7) -> 5418.2463 | N10: =IF('Model inputs'!V6="","",'Model inputs'!V6) -> 2361 | O10: =IF('Model inputs'!V8="","",'Model inputs'!V8) -> 3758.625 | P10: =IF('Model inputs'!V9="","",'Model inputs'!V9) -> 5034.908 | Q10: =IF('Model inputs'!V7="","",'Model inputs'!V7) -> 9769.9904 | R10: =IF('Model inputs'!Y6="","",'Model inputs'!Y6) -> 2300.55 | S10: =IF('Model inputs'!Y8="","",'Model inputs'!Y8) -> 4113.075 | T10: =IF('Model inputs'!Y9="","",'Model inputs'!Y9) -> 9182.4522 | U10: =IF('Model inputs'!Y7="","",'Model inputs'!Y7) -> 18459.653 | V10: =IF('Model inputs'!AB6="","",'Model inputs'!AB6) -> 2240.1 | W10: =IF('Model inputs'!AB8="","",'Model inputs'!AB8) -> 4467.525 | X10: =IF('Model inputs'!AB9="","",'Model inputs'!AB9) -> 13905.903 | Y10: =IF('Model inputs'!AB7="","",'Model inputs'!AB7) -> 28013.176 | Z10: =IF('Model inputs'!AE6="","",'Model inputs'!AE6) -> 2179.65 | AA10: =IF('Model inputs'!AE8="","",'Model inputs'!AE8) -> 4821.975 | AB10: =IF('Model inputs'!AE9="","",'Model inputs'!AE9) -> 18629.354 | AC10: =IF('Model inputs'!AE7="","",'Model inputs'!AE7) -> 37566.698 | AD10: =IF('Model inputs'!AH6="","",'Model inputs'!AH6) -> 2119.2 | AE10: =IF('Model inputs'!AH8="","",'Model inputs'!AH8) -> 5176.425 | AF10: =IF('Model inputs'!AH9="","",'Model inputs'!AH9) -> 23352.805 | AG10: =IF('Model inputs'!AH7="","",'Model inputs'!AH7) -> 47120.22
A11: Cash balance with salary | B11: =IF('Model inputs'!M10="","",'Model inputs'!M10) -> -3457.65 | C11: =IF('Model inputs'!M12="","",'Model inputs'!M12) -> -3304.725 | D11: =IF('Model inputs'!M13="","",'Model inputs'!M13) -> -3482.025 | E11: =IF('Model inputs'!M11="","",'Model inputs'!M11) -> -3325.4437 | F11: =IF('Model inputs'!P10="","",'Model inputs'!P10) -> -9518.1 | G11: =IF('Model inputs'!P12="","",'Model inputs'!P12) -> -8950.275 | H11: =IF('Model inputs'!P13="","",'Model inputs'!P13) -> -9394.0582 | I11: =IF('Model inputs'!P11="","",'Model inputs'!P11) -> -8560.9667 | J11: =IF('Model inputs'!S10="","",'Model inputs'!S10) -> -15578.55 | K11: =IF('Model inputs'!S12="","",'Model inputs'!S12) -> -14595.825 | L11: =IF('Model inputs'!S13="","",'Model inputs'!S13) -> -14736.154 | M11: =IF('Model inputs'!S11="","",'Model inputs'!S11) -> -12581.754 | N11: =IF('Model inputs'!V10="","",'Model inputs'!V10) -> -21639 | O11: =IF('Model inputs'!V12="","",'Model inputs'!V12) -> -20241.375 | P11: =IF('Model inputs'!V13="","",'Model inputs'!V13) -> -18965.092 | Q11: =IF('Model inputs'!V11="","",'Model inputs'!V11) -> -14230.01 | R11: =IF('Model inputs'!Y10="","",'Model inputs'!Y10) -> -27699.45 | S11: =IF('Model inputs'!Y12="","",'Model inputs'!Y12) -> -25886.925 | T11: =IF('Model inputs'!Y13="","",'Model inputs'!Y13) -> -20817.548 | U11: =IF('Model inputs'!Y11="","",'Model inputs'!Y11) -> -11540.347 | V11: =IF('Model inputs'!AB10="","",'Model inputs'!AB10) -> -33759.9 | W11: =IF('Model inputs'!AB12="","",'Model inputs'!AB12) -> -31532.475 | X11: =IF('Model inputs'!AB13="","",'Model inputs'!AB13) -> -22094.097 | Y11: =IF('Model inputs'!AB11="","",'Model inputs'!AB11) -> -7986.8245 | Z11: =IF('Model inputs'!AE10="","",'Model inputs'!AE10) -> -39820.35 | AA11: =IF('Model inputs'!AE12="","",'Model inputs'!AE12) -> -37178.025 | AB11: =IF('Model inputs'!AE13="","",'Model inputs'!AE13) -> -23370.646 | AC11: =IF('Model inputs'!AE11="","",'Model inputs'!AE11) -> -4433.302 | AD11: =IF('Model inputs'!AH10="","",'Model inputs'!AH10) -> -45880.8 | AE11: =IF('Model inputs'!AH12="","",'Model inputs'!AH12) -> -42823.575 | AF11: =IF('Model inputs'!AH13="","",'Model inputs'!AH13) -> -24647.195 | AG11: =IF('Model inputs'!AH11="","",'Model inputs'!AH11) -> -879.7795

Sheet Model inputs
A1: Model inputs
A2: Integration values are aggregated snapshots; raw source records are not included.
A4: Variables
A5: Variable / segment | B5: 2026-01 | C5: 2026-02 | D5: 2026-03 | E5: 2026-04 | F5: 2026-05 | G5: 2026-06 | H5: 2026-07 | I5: 2026-08 | J5: 2026-09 | K5: 2026-10 | L5: 2026-11 | M5: 2026-12 | N5: 2027-01 | O5: 2027-02 | P5: 2027-03 | Q5: 2027-04 | R5: 2027-05 | S5: 2027-06 | T5: 2027-07 | U5: 2027-08 | V5: 2027-09 | W5: 2027-10 | X5: 2027-11 | Y5: 2027-12 | Z5: 2028-01 | AA5: 2028-02 | AB5: 2028-03 | AC5: 2028-04 | AD5: 2028-05 | AE5: 2028-06 | AF5: 2028-07 | AG5: 2028-08 | AH5: 2028-09 | AI5: Value
A6: Cash balance · Main Scenario | B6: =IF('Model inputs'!AI74="","",'Model inputs'!AI74) -> 3000 | C6: =IF('Model inputs'!AI74="","",'Model inputs'!AI74) -> 3000 | D6: =IF('Model inputs'!AI74="","",'Model inputs'!AI74) -> 3000 | E6: =IF('Model inputs'!AI74="","",'Model inputs'!AI74) -> 3000 | F6: =IF('Model inputs'!AI74="","",'Model inputs'!AI74) -> 3000 | G6: =IF('Model inputs'!AI74="","",'Model inputs'!AI74) -> 3000 | H6: =IF('Model inputs'!AI74="","",'Model inputs'!AI74) -> 3000 | I6: =IF('Model inputs'!AI74="","",'Model inputs'!AI74) -> 3000 | J6: =IF('Model inputs'!AI74="","",'Model inputs'!AI74) -> 3000 | K6: ='Model inputs'!J6+'Model inputs'!K22 -> 2830 | L6: ='Model inputs'!K6+'Model inputs'!L22 -> 2562.5 | M6: ='Model inputs'!L6+'Model inputs'!M22 -> 2542.35 | N6: ='Model inputs'!M6+'Model inputs'!N22 -> 2522.2 | O6: ='Model inputs'!N6+'Model inputs'!O22 -> 2502.05 | P6: ='Model inputs'!O6+'Model inputs'!P22 -> 2481.9 | Q6: ='Model inputs'!P6+'Model inputs'!Q22 -> 2461.75 | R6: ='Model inputs'!Q6+'Model inputs'!R22 -> 2441.6 | ... AH6: ='Model inputs'!AG6+'Model inputs'!AH22 -> 2119.2
A7: Cash balance · Growth · $0.60 | B7: =IF('Model inputs'!AI75="","",'Model inputs'!AI75) -> 3000 | C7: =IF('Model inputs'!AI75="","",'Model inputs'!AI75) -> 3000 | D7: =IF('Model inputs'!AI75="","",'Model inputs'!AI75) -> 3000 | E7: =IF('Model inputs'!AI75="","",'Model inputs'!AI75) -> 3000 | F7: =IF('Model inputs'!AI75="","",'Model inputs'!AI75) -> 3000 | G7: =IF('Model inputs'!AI75="","",'Model inputs'!AI75) -> 3000 | H7: =IF('Model inputs'!AI75="","",'Model inputs'!AI75) -> 3000 | I7: =IF('Model inputs'!AI75="","",'Model inputs'!AI75) -> 3000 | J7: =IF('Model inputs'!AI75="","",'Model inputs'!AI75) -> 3000 | K7: ='Model inputs'!J7+'Model inputs'!K23 -> 2830 | L7: ='Model inputs'!K7+'Model inputs'!L23 -> 2577.125 | M7: ='Model inputs'!L7+'Model inputs'!M23 -> 2674.5563 | N7: ='Model inputs'!M7+'Model inputs'!N23 -> 2838.8453 | O7: ='Model inputs'!N7+'Model inputs'!O23 -> 3086.7066 | P7: ='Model inputs'!O7+'Model inputs'!P23 -> 3439.0333 | Q7: ='Model inputs'!P7+'Model inputs'!Q23 -> 3921.9416 | R7: ='Model inputs'!Q7+'Model inputs'!R23 -> 4568.077 | ... AH7: ='Model inputs'!AG7+'Model inputs'!AH23 -> 47120.22
A8: Cash balance · Base · $0.60 | B8: =IF('Model inputs'!AI76="","",'Model inputs'!AI76) -> 3000 | C8: =IF('Model inputs'!AI76="","",'Model inputs'!AI76) -> 3000 | D8: =IF('Model inputs'!AI76="","",'Model inputs'!AI76) -> 3000 | E8: =IF('Model inputs'!AI76="","",'Model inputs'!AI76) -> 3000 | F8: =IF('Model inputs'!AI76="","",'Model inputs'!AI76) -> 3000 | G8: =IF('Model inputs'!AI76="","",'Model inputs'!AI76) -> 3000 | H8: =IF('Model inputs'!AI76="","",'Model inputs'!AI76) -> 3000 | I8: =IF('Model inputs'!AI76="","",'Model inputs'!AI76) -> 3000 | J8: =IF('Model inputs'!AI76="","",'Model inputs'!AI76) -> 3000 | K8: ='Model inputs'!J8+'Model inputs'!K24 -> 2830 | L8: ='Model inputs'!K8+'Model inputs'!L24 -> 2577.125 | M8: ='Model inputs'!L8+'Model inputs'!M24 -> 2695.275 | N8: ='Model inputs'!M8+'Model inputs'!N24 -> 2813.425 | O8: ='Model inputs'!N8+'Model inputs'!O24 -> 2931.575 | P8: ='Model inputs'!O8+'Model inputs'!P24 -> 3049.725 | Q8: ='Model inputs'!P8+'Model inputs'!Q24 -> 3167.875 | R8: ='Model inputs'!Q8+'Model inputs'!R24 -> 3286.025 | ... AH8: ='Model inputs'!AG8+'Model inputs'!AH24 -> 5176.425
A9: Cash balance · Growth · $0.34 | B9: =IF('Model inputs'!AI77="","",'Model inputs'!AI77) -> 3000 | C9: =IF('Model inputs'!AI77="","",'Model inputs'!AI77) -> 3000 | D9: =IF('Model inputs'!AI77="","",'Model inputs'!AI77) -> 3000 | E9: =IF('Model inputs'!AI77="","",'Model inputs'!AI77) -> 3000 | F9: =IF('Model inputs'!AI77="","",'Model inputs'!AI77) -> 3000 | G9: =IF('Model inputs'!AI77="","",'Model inputs'!AI77) -> 3000 | H9: =IF('Model inputs'!AI77="","",'Model inputs'!AI77) -> 3000 | I9: =IF('Model inputs'!AI77="","",'Model inputs'!AI77) -> 3000 | J9: =IF('Model inputs'!AI77="","",'Model inputs'!AI77) -> 3000 | K9: ='Model inputs'!J9+'Model inputs'!K25 -> 2830 | L9: ='Model inputs'!K9+'Model inputs'!L25 -> 2562.5 | M9: ='Model inputs'!L9+'Model inputs'!M25 -> 2517.975 | N9: ='Model inputs'!M9+'Model inputs'!N25 -> 2504.8187 | O9: ='Model inputs'!N9+'Model inputs'!O25 -> 2530.8734 | P9: ='Model inputs'!O9+'Model inputs'!P25 -> 2605.9418 | Q9: ='Model inputs'!P9+'Model inputs'!Q25 -> 2742.2772 | R9: ='Model inputs'!Q9+'Model inputs'!R25 -> 2955.1966 | ... AH9: ='Model inputs'!AG9+'Model inputs'!AH25 -> 23352.805
A10: Cash balance with salary · Main Scenario | B10: =IF('Model inputs'!AI74="","",'Model inputs'!AI74) -> 3000 | C10: =IF('Model inputs'!AI74="","",'Model inputs'!AI74) -> 3000 | D10: =IF('Model inputs'!AI74="","",'Model inputs'!AI74) -> 3000 | E10: =IF('Model inputs'!AI74="","",'Model inputs'!AI74) -> 3000 | F10: =IF('Model inputs'!AI74="","",'Model inputs'!AI74) -> 3000 | G10: =IF('Model inputs'!AI74="","",'Model inputs'!AI74) -> 3000 | H10: =IF('Model inputs'!AI74="","",'Model inputs'!AI74) -> 3000 | I10: =IF('Model inputs'!AI74="","",'Model inputs'!AI74) -> 3000 | J10: =IF('Model inputs'!AI74="","",'Model inputs'!AI74) -> 3000 | K10: ='Model inputs'!J10+'Model inputs'!K66 -> 830 | L10: ='Model inputs'!K10+'Model inputs'!L66 -> -1437.5 | M10: ='Model inputs'!L10+'Model inputs'!M66 -> -3457.65 | N10: ='Model inputs'!M10+'Model inputs'!N66 -> -5477.8 | O10: ='Model inputs'!N10+'Model inputs'!O66 -> -7497.95 | P10: ='Model inputs'!O10+'Model inputs'!P66 -> -9518.1 | Q10: ='Model inputs'!P10+'Model inputs'!Q66 -> -11538.25 | R10: ='Model inputs'!Q10+'Model inputs'!R66 -> -13558.4 | ... AH10: ='Model inputs'!AG10+'Model inputs'!AH66 -> -45880.8
A11: Cash balance with salary · Growth · $0.60 | B11: =IF('Model inputs'!AI75="","",'Model inputs'!AI75) -> 3000 | C11: =IF('Model inputs'!AI75="","",'Model inputs'!AI75) -> 3000 | D11: =IF('Model inputs'!AI75="","",'Model inputs'!AI75) -> 3000 | E11: =IF('Model inputs'!AI75="","",'Model inputs'!AI75) -> 3000 | F11: =IF('Model inputs'!AI75="","",'Model inputs'!AI75) -> 3000 | G11: =IF('Model inputs'!AI75="","",'Model inputs'!AI75) -> 3000 | H11: =IF('Model inputs'!AI75="","",'Model inputs'!AI75) -> 3000 | I11: =IF('Model inputs'!AI75="","",'Model inputs'!AI75) -> 3000 | J11: =IF('Model inputs'!AI75="","",'Model inputs'!AI75) -> 3000 | K11: ='Model inputs'!J11+'Model inputs'!K67 -> 830 | L11: ='Model inputs'!K11+'Model inputs'!L67 -> -1422.875 | M11: ='Model inputs'!L11+'Model inputs'!M67 -> -3325.4437 | N11: ='Model inputs'!M11+'Model inputs'!N67 -> -5161.1547 | O11: ='Model inputs'!N11+'Model inputs'!O67 -> -6913.2934 | P11: ='Model inputs'!O11+'Model inputs'!P67 -> -8560.9667 | Q11: ='Model inputs'!P11+'Model inputs'!Q67 -> -10078.058 | R11: ='Model inputs'!Q11+'Model inputs'!R67 -> -11431.923 | ... AH11: ='Model inputs'!AG11+'Model inputs'!AH67 -> -879.7795
A12: Cash balance with salary · Base · $0.60 | B12: =IF('Model inputs'!AI76="","",'Model inputs'!AI76) -> 3000 | C12: =IF('Model inputs'!AI76="","",'Model inputs'!AI76) -> 3000 | D12: =IF('Model inputs'!AI76="","",'Model inputs'!AI76) -> 3000 | E12: =IF('Model inputs'!AI76="","",'Model inputs'!AI76) -> 3000 | F12: =IF('Model inputs'!AI76="","",'Model inputs'!AI76) -> 3000 | G12: =IF('Model inputs'!AI76="","",'Model inputs'!AI76) -> 3000 | H12: =IF('Model inputs'!AI76="","",'Model inputs'!AI76) -> 3000 | I12: =IF('Model inputs'!AI76="","",'Model inputs'!AI76) -> 3000 | J12: =IF('Model inputs'!AI76="","",'Model inputs'!AI76) -> 3000 | K12: ='Model inputs'!J12+'Model inputs'!K68 -> 830 | L12: ='Model inputs'!K12+'Model inputs'!L68 -> -1422.875 | M12: ='Model inputs'!L12+'Model inputs'!M68 -> -3304.725 | N12: ='Model inputs'!M12+'Model inputs'!N68 -> -5186.575 | O12: ='Model inputs'!N12+'Model inputs'!O68 -> -7068.425 | P12: ='Model inputs'!O12+'Model inputs'!P68 -> -8950.275 | Q12: ='Model inputs'!P12+'Model inputs'!Q68 -> -10832.125 | R12: ='Model inputs'!Q12+'Model inputs'!R68 -> -12713.975 | ... AH12: ='Model inputs'!AG12+'Model inputs'!AH68 -> -42823.575
A13: Cash balance with salary · Growth · $0.34 | B13: =IF('Model inputs'!AI77="","",'Model inputs'!AI77) -> 3000 | C13: =IF('Model inputs'!AI77="","",'Model inputs'!AI77) -> 3000 | D13: =IF('Model inputs'!AI77="","",'Model inputs'!AI77) -> 3000 | E13: =IF('Model inputs'!AI77="","",'Model inputs'!AI77) -> 3000 | F13: =IF('Model inputs'!AI77="","",'Model inputs'!AI77) -> 3000 | G13: =IF('Model inputs'!AI77="","",'Model inputs'!AI77) -> 3000 | H13: =IF('Model inputs'!AI77="","",'Model inputs'!AI77) -> 3000 | I13: =IF('Model inputs'!AI77="","",'Model inputs'!AI77) -> 3000 | J13: =IF('Model inputs'!AI77="","",'Model inputs'!AI77) -> 3000 | K13: ='Model inputs'!J13+'Model inputs'!K69 -> 830 | L13: ='Model inputs'!K13+'Model inputs'!L69 -> -1437.5 | M13: ='Model inputs'!L13+'Model inputs'!M69 -> -3482.025 | N13: ='Model inputs'!M13+'Model inputs'!N69 -> -5495.1812 | O13: ='Model inputs'!N13+'Model inputs'!O69 -> -7469.1266 | P13: ='Model inputs'!O13+'Model inputs'!P69 -> -9394.0582 | Q13: ='Model inputs'!P13+'Model inputs'!Q69 -> -11257.723 | R13: ='Model inputs'!Q13+'Model inputs'!R69 -> -13044.803 | ... AH13: ='Model inputs'!AG13+'Model inputs'!AH69 -> -24647.195
A14: Gross profit · Main Scenario | B14: 0 | C14: 0 | D14: 0 | E14: 0 | F14: 0 | G14: 0 | H14: 0 | I14: 0 | J14: 0 | K14: ='Model inputs'!K30-'Model inputs'!K38 -> 0 | L14: ='Model inputs'!L30-'Model inputs'!L38 -> 149.85 | M14: ='Model inputs'!M30-'Model inputs'!M38 -> 149.85 | N14: ='Model inputs'!N30-'Model inputs'!N38 -> 149.85 | O14: ='Model inputs'!O30-'Model inputs'!O38 -> 149.85 | P14: ='Model inputs'!P30-'Model inputs'!P38 -> 149.85 | Q14: ='Model inputs'!Q30-'Model inputs'!Q38 -> 149.85 | R14: ='Model inputs'!R30-'Model inputs'!R38 -> 149.85 | ... AH14: ='Model inputs'!AH30-'Model inputs'!AH38 -> 149.85
A15: Gross profit · Growth · $0.60 | B15: 0 | C15: 0 | D15: 0 | E15: 0 | F15: 0 | G15: 0 | H15: 0 | I15: 0 | J15: 0 | K15: ='Model inputs'!K31-'Model inputs'!K39 -> 0 | L15: ='Model inputs'!L31-'Model inputs'!L39 -> 288.15 | M15: ='Model inputs'!M31-'Model inputs'!M39 -> 360.1875 | N15: ='Model inputs'!N31-'Model inputs'!N39 -> 450.23438 | O15: ='Model inputs'!O31-'Model inputs'!O39 -> 562.79297 | P15: ='Model inputs'!P31-'Model inputs'!P39 -> 703.49121 | Q15: ='Model inputs'!Q31-'Model inputs'!Q39 -> 879.36401 | R15: ='Model inputs'!R31-'Model inputs'!R39 -> 1099.205 | ... AH15: ='Model inputs'!AH31-'Model inputs'!AH39 -> 3354.5075
A16: Gross profit · Base · $0.60 | B16: 0 | C16: 0 | D16: 0 | E16: 0 | F16: 0 | G16: 0 | H16: 0 | I16: 0 | J16: 0 | K16: ='Model inputs'!K32-'Model inputs'!K40 -> 0 | L16: ='Model inputs'!L32-'Model inputs'!L40 -> 288.15 | M16: ='Model inputs'!M32-'Model inputs'!M40 -> 288.15 | N16: ='Model inputs'!N32-'Model inputs'!N40 -> 288.15 | O16: ='Model inputs'!O32-'Model inputs'!O40 -> 288.15 | P16: ='Model inputs'!P32-'Model inputs'!P40 -> 288.15 | Q16: ='Model inputs'!Q32-'Model inputs'!Q40 -> 288.15 | R16: ='Model inputs'!R32-'Model inputs'!R40 -> 288.15 | ... AH16: ='Model inputs'!AH32-'Model inputs'!AH40 -> 288.15
A17: Gross profit · Growth · $0.34 | B17: 0 | C17: 0 | D17: 0 | E17: 0 | F17: 0 | G17: 0 | H17: 0 | I17: 0 | J17: 0 | K17: ='Model inputs'!K33-'Model inputs'!K41 -> 0 | L17: ='Model inputs'!L33-'Model inputs'!L41 -> 149.85 | M17: ='Model inputs'!M33-'Model inputs'!M41 -> 187.3125 | N17: ='Model inputs'!N33-'Model inputs'!N41 -> 234.14063 | O17: ='Model inputs'!O33-'Model inputs'!O41 -> 292.67578 | P17: ='Model inputs'!P33-'Model inputs'!P41 -> 365.84473 | Q17: ='Model inputs'!Q33-'Model inputs'!Q41 -> 457.30591 | R17: ='Model inputs'!R33-'Model inputs'!R41 -> 571.63239 | ... AH17: ='Model inputs'!AH33-'Model inputs'!AH41 -> 1744.4836
A18: Jobs attempted · Main Scenario | B18: 0 | C18: 0 | D18: 0 | E18: 0 | F18: 0 | G18: 0 | H18: 0 | I18: 0 | J18: 0 | K18: =IF(IF(IF(ISERROR('Model inputs'!K62<1),'Model inputs'!K62<1,IF('Model inputs'!K62="","",'Model inputs'!K62<1))="",FALSE,IF(ISERROR('Model inputs'!K62<1),'Model inputs'!K62<1,IF('Model inputs'!K62="","",'Model inputs'!K62<1))),0,'Model inputs'!AI50*IF(AND((1+'Model inputs'!AI58)=0,(MIN('Model inputs'!K62,'Model inputs'!AI46)-1)=0),SQRT(-1),(1+'Model inputs'!AI58)^(MIN('Model inputs'!K62,'Model inputs'!AI46)-1))*'Model inputs'!AI82) -> 0 | L18: =IF(IF(IF(ISERROR('Model inputs'!L62<1),'Model inputs'!L62<1,IF('Model inputs'!L62="","",'Model inputs'!L62<1))="",FALSE,IF(ISERROR('Model inputs'!L62<1),'Model inputs'!L62<1,IF('Model inputs'!L62="","",'Model inputs'!L62<1))),0,'Model inputs'!AI50*IF(AND((1+'Model inputs'!AI58)=0,(MIN('Model inputs'!L62,'Model inputs'!AI46)-1)=0),SQRT(-1),(1+'Model inputs'!AI58)^(MIN('Model inputs'!L62,'Model inputs'!AI46)-1))*'Model inputs'!AI82) -> 1000 | M18: =IF(IF(IF(ISERROR('Model inputs'!M62<1),'Model inputs'!M62<1,IF('Model inputs'!M62="","",'Model inputs'!M62<1))="",FALSE,IF(ISERROR('Model inputs'!M62<1),'Model inputs'!M62<1,IF('Model inputs'!M62="","",'Model inputs'!M62<1))),0,'Model inputs'!AI50*IF(AND((1+'Model inputs'!AI58)=0,(MIN('Model inputs'!M62,'Model inputs'!AI46)-1)=0),SQRT(-1),(1+'Model inputs'!AI58)^(MIN('Model inputs'!M62,'Model inputs'!AI46)-1))*'Model inputs'!AI82) -> 1000 | N18: =IF(IF(IF(ISERROR('Model inputs'!N62<1),'Model inputs'!N62<1,IF('Model inputs'!N62="","",'Model inputs'!N62<1))="",FALSE,IF(ISERROR('Model inputs'!N62<1),'Model inputs'!N62<1,IF('Model inputs'!N62="","",'Model inputs'!N62<1))),0,'Model inputs'!AI50*IF(AND((1+'Model inputs'!AI58)=0,(MIN('Model inputs'!N62,'Model inputs'!AI46)-1)=0),SQRT(-1),(1+'Model inputs'!AI58)^(MIN('Model inputs'!N62,'Model inputs'!AI46)-1))*'Model inputs'!AI82) -> 1000 | O18: =IF(IF(IF(ISERROR('Model inputs'!O62<1),'Model inputs'!O62<1,IF('Model inputs'!O62="","",'Model inputs'!O62<1))="",FALSE,IF(ISERROR('Model inputs'!O62<1),'Model inputs'!O62<1,IF('Model inputs'!O62="","",'Model inputs'!O62<1))),0,'Model inputs'!AI50*IF(AND((1+'Model inputs'!AI58)=0,(MIN('Model inputs'!O62,'Model inputs'!AI46)-1)=0),SQRT(-1),(1+'Model inputs'!AI58)^(MIN('Model inputs'!O62,'Model inputs'!AI46)-1))*'Model inputs'!AI82) -> 1000 | P18: =IF(IF(IF(ISERROR('Model inputs'!P62<1),'Model inputs'!P62<1,IF('Model inputs'!P62="","",'Model inputs'!P62<1))="",FALSE,IF(ISERROR('Model inputs'!P62<1),'Model inputs'!P62<1,IF('Model inputs'!P62="","",'Model inputs'!P62<1))),0,'Model inputs'!AI50*IF(AND((1+'Model inputs'!AI58)=0,(MIN('Model inputs'!P62,'Model inputs'!AI46)-1)=0),SQRT(-1),(1+'Model inputs'!AI58)^(MIN('Model inputs'!P62,'Model inputs'!AI46)-1))*'Model inputs'!AI82) -> 1000 | Q18: =IF(IF(IF(ISERROR('Model inputs'!Q62<1),'Model inputs'!Q62<1,IF('Model inputs'!Q62="","",'Model inputs'!Q62<1))="",FALSE,IF(ISERROR('Model inputs'!Q62<1),'Model inputs'!Q62<1,IF('Model inputs'!Q62="","",'Model inputs'!Q62<1))),0,'Model inputs'!AI50*IF(AND((1+'Model inputs'!AI58)=0,(MIN('Model inputs'!Q62,'Model inputs'!AI46)-1)=0),SQRT(-1),(1+'Model inputs'!AI58)^(MIN('Model inputs'!Q62,'Model inputs'!AI46)-1))*'Model inputs'!AI82) -> 1000 | R18: =IF(IF(IF(ISERROR('Model inputs'!R62<1),'Model inputs'!R62<1,IF('Model inputs'!R62="","",'Model inputs'!R62<1))="",FALSE,IF(ISERROR('Model inputs'!R62<1),'Model inputs'!R62<1,IF('Model inputs'!R62="","",'Model inputs'!R62<1))),0,'Model inputs'!AI50*IF(AND((1+'Model inputs'!AI58)=0,(MIN('Model inputs'!R62,'Model inputs'!AI46)-1)=0),SQRT(-1),(1+'Model inputs'!AI58)^(MIN('Model inputs'!R62,'Model inputs'!AI46)-1))*'Model inputs'!AI82) -> 1000 | S18: =IF(IF(IF(ISERROR('Model inputs'!S62<1),'Model inputs'!S62<1,IF('Model inputs'!S62="","",'Model inputs'!S62<1))="",FALSE,IF(ISERROR('Model inputs'!S62<1),'Model inputs'!S62<1,IF('Model inputs'!S62="","",'Model inputs'!S62<1))),0,'Model inputs'!AI50*IF(AND((1+'Model inputs'!AI58)=0,(MIN('Model inputs'!S62,'Model inputs'!AI46)-1)=0),SQRT(-1),(1+'Model inputs'!AI58)^(MIN('Model inputs'!S62,'Model inputs'!AI46)-1))*'Model inputs'!AI82) -> 1000 | T18: =IF(IF(IF(ISERROR('Model inputs'!T62<1),'Model inputs'!T62<1,IF('Model inputs'!T62="","",'Model inputs'!T62<1))="",FALSE,IF(ISERROR('Model inputs'!T62<1),'Model inputs'!T62<1,IF('Model inputs'!T62="","",'Model inputs'!T62<1))),0,'Model inputs'!AI50*IF(AND((1+'Model inputs'!AI58)=0,(MIN('Model inputs'!T62,'Model inputs'!AI46)-1)=0),SQRT(-1),(1+'Model inputs'!AI58)^(MIN('Model inputs'!T62,'Model inputs'!AI46)-1))*'Model inputs'!AI82) -> 1000 | U18: =IF(IF(IF(ISERROR('Model inputs'!U62<1),'Model inputs'!U62<1,IF('Model inputs'!U62="","",'Model inputs'!U62<1))="",FALSE,IF(ISERROR('Model inputs'!U62<1),'Model inputs'!U62<1,IF('Model inputs'!U62="","",'Model inputs'!U62<1))),0,'Model inputs'!AI50*IF(AND((1+'Model inputs'!AI58)=0,(MIN('Model inputs'!U62,'Model inputs'!AI46)-1)=0),SQRT(-1),(1+'Model inputs'!AI58)^(MIN('Model inputs'!U62,'Model inputs'!AI46)-1))*'Model inputs'!AI82) -> 1000 | V18: =IF(IF(IF(ISERROR('Model inputs'!V62<1),'Model inputs'!V62<1,IF('Model inputs'!V62="","",'Model inputs'!V62<1))="",FALSE,IF(ISERROR('Model inputs'!V62<1),'Model inputs'!V62<1,IF('Model inputs'!V62="","",'Model inputs'!V62<1))),0,'Model inputs'!AI50*IF(AND((1+'Model inputs'!AI58)=0,(MIN('Model inputs'!V62,'Model inputs'!AI46)-1)=0),SQRT(-1),(1+'Model inputs'!AI58)^(MIN('Model inputs'!V62,'Model inputs'!AI46)-1))*'Model inputs'!AI82) -> 1000 | W18: =IF(IF(IF(ISERROR('Model inputs'!W62<1),'Model inputs'!W62<1,IF('Model inputs'!W62="","",'Model inputs'!W62<1))="",FALSE,IF(ISERROR('Model inputs'!W62<1),'Model inputs'!W62<1,IF('Model inputs'!W62="","",'Model inputs'!W62<1))),0,'Model inputs'!AI50*IF(AND((1+'Model inputs'!AI58)=0,(MIN('Model inputs'!W62,'Model inputs'!AI46)-1)=0),SQRT(-1),(1+'Model inputs'!AI58)^(MIN('Model inputs'!W62,'Model inputs'!AI46)-1))*'Model inputs'!AI82) -> 1000 | X18: =IF(IF(IF(ISERROR('Model inputs'!X62<1),'Model inputs'!X62<1,IF('Model inputs'!X62="","",'Model inputs'!X62<1))="",FALSE,IF(ISERROR('Model inputs'!X62<1),'Model inputs'!X62<1,IF('Model inputs'!X62="","",'Model inputs'!X62<1))),0,'Model inputs'!AI50*IF(AND((1+'Model inputs'!AI58)=0,(MIN('Model inputs'!X62,'Model inputs'!AI46)-1)=0),SQRT(-1),(1+'Model inputs'!AI58)^(MIN('Model inputs'!X62,'Model inputs'!AI46)-1))*'Model inputs'!AI82) -> 1000 | Y18: =IF(IF(IF(ISERROR('Model inputs'!Y62<1),'Model inputs'!Y62<1,IF('Model inputs'!Y62="","",'Model inputs'!Y62<1))="",FALSE,IF(ISERROR('Model inputs'!Y62<1),'Model inputs'!Y62<1,IF('Model inputs'!Y62="","",'Model inputs'!Y62<1))),0,'Model inputs'!AI50*IF(AND((1+'Model inputs'!AI58)=0,(MIN('Model inputs'!Y62,'Model inputs'!AI46)-1)=0),SQRT(-1),(1+'Model inputs'!AI58)^(MIN('Model inputs'!Y62,'Model inputs'!AI46)-1))*'Model inputs'!AI82) -> 1000 | Z18: =IF(IF(IF(ISERROR('Model inputs'!Z62<1),'Model inputs'!Z62<1,IF('Model inputs'!Z62="","",'Model inputs'!Z62<1))="",FALSE,IF(ISERROR('Model inputs'!Z62<1),'Model inputs'!Z62<1,IF('Model inputs'!Z62="","",'Model inputs'!Z62<1))),0,'Model inputs'!AI50*IF(AND((1+'Model inputs'!AI58)=0,(MIN('Model inputs'!Z62,'Model inputs'!AI46)-1)=0),SQRT(-1),(1+'Model inputs'!AI58)^(MIN('Model inputs'!Z62,'Model inputs'!AI46)-1))*'Model inputs'!AI82) -> 1000 | AA18: =IF(IF(IF(ISERROR('Model inputs'!AA62<1),'Model inputs'!AA62<1,IF('Model inputs'!AA62="","",'Model inputs'!AA62<1))="",FALSE,IF(ISERROR('Model inputs'!AA62<1),'Model inputs'!AA62<1,IF('Model inputs'!AA62="","",'Model inputs'!AA62<1))),0,'Model inputs'!AI50*IF(AND((1+'Model inputs'!AI58)=0,(MIN('Model inputs'!AA62,'Model inputs'!AI46)-1)=0),SQRT(-1),(1+'Model inputs'!AI58)^(MIN('Model inputs'!AA62,'Model inputs'!AI46)-1))*'Model inputs'!AI82) -> 1000 | AB18: =IF(IF(IF(ISERROR('Model inputs'!AB62<1),'Model inputs'!AB62<1,IF('Model inputs'!AB62="","",'Model inputs'!AB62<1))="",FALSE,IF(ISERROR('Model inputs'!AB62<1),'Model inputs'!AB62<1,IF('Model inputs'!AB62="","",'Model inputs'!AB62<1))),0,'Model inputs'!AI50*IF(AND((1+'Model inputs'!AI58)=0,(MIN('Model inputs'!AB62,'Model inputs'!AI46)-1)=0),SQRT(-1),(1+'Model inputs'!AI58)^(MIN('Model inputs'!AB62,'Model inputs'!AI46)-1))*'Model inputs'!AI82) -> 1000 | AC18: =IF(IF(IF(ISERROR('Model inputs'!AC62<1),'Model inputs'!AC62<1,IF('Model inputs'!AC62="","",'Model inputs'!AC62<1))="",FALSE,IF(ISERROR('Model inputs'!AC62<1),'Model inputs'!AC62<1,IF('Model inputs'!AC62="","",'Model inputs'!AC62<1))),0,'Model inputs'!AI50*IF(AND((1+'Model inputs'!AI58)=0,(MIN('Model inputs'!AC62,'Model inputs'!AI46)-1)=0),SQRT(-1),(1+'Model inputs'!AI58)^(MIN('Model inputs'!AC62,'Model inputs'!AI46)-1))*'Model inputs'!AI82) -> 1000 | AD18: =IF(IF(IF(ISERROR('Model inputs'!AD62<1),'Model inputs'!AD62<1,IF('Model inputs'!AD62="","",'Model inputs'!AD62<1))="",FALSE,IF(ISERROR('Model inputs'!AD62<1),'Model inputs'!AD62<1,IF('Model inputs'!AD62="","",'Model inputs'!AD62<1))),0,'Model inputs'!AI50*IF(AND((1+'Model inputs'!AI58)=0,(MIN('Model inputs'!AD62,'Model inputs'!AI46)-1)=0),SQRT(-1),(1+'Model inputs'!AI58)^(MIN('Model inputs'!AD62,'Model inputs'!AI46)-1))*'Model inputs'!AI82) -> 1000 | AE18: =IF(IF(IF(ISERROR('Model inputs'!AE62<1),'Model inputs'!AE62<1,IF('Model inputs'!AE62="","",'Model inputs'!AE62<1))="",FALSE,IF(ISERROR('Model inputs'!AE62<1),'Model inputs'!AE62<1,IF('Model inputs'!AE62="","",'Model inputs'!AE62<1))),0,'Model inputs'!AI50*IF(AND((1+'Model inputs'!AI58)=0,(MIN('Model inputs'!AE62,'Model inputs'!AI46)-1)=0),SQRT(-1),(1+'Model inputs'!AI58)^(MIN('Model inputs'!AE62,'Model inputs'!AI46)-1))*'Model inputs'!AI82) -> 1000 | AF18: =IF(IF(IF(ISERROR('Model inputs'!AF62<1),'Model inputs'!AF62<1,IF('Model inputs'!AF62="","",'Model inputs'!AF62<1))="",FALSE,IF(ISERROR('Model inputs'!AF62<1),'Model inputs'!AF62<1,IF('Model inputs'!AF62="","",'Model inputs'!AF62<1))),0,'Model inputs'!AI50*IF(AND((1+'Model inputs'!AI58)=0,(MIN('Model inputs'!AF62,'Model inputs'!AI46)-1)=0),SQRT(-1),(1+'Model inputs'!AI58)^(MIN('Model inputs'!AF62,'Model inputs'!AI46)-1))*'Model inputs'!AI82) -> 1000 | AG18: =IF(IF(IF(ISERROR('Model inputs'!AG62<1),'Model inputs'!AG62<1,IF('Model inputs'!AG62="","",'Model inputs'!AG62<1))="",FALSE,IF(ISERROR('Model inputs'!AG62<1),'Model inputs'!AG62<1,IF('Model inputs'!AG62="","",'Model inputs'!AG62<1))),0,'Model inputs'!AI50*IF(AND((1+'Model inputs'!AI58)=0,(MIN('Model inputs'!AG62,'Model inputs'!AI46)-1)=0),SQRT(-1),(1+'Model inputs'!AI58)^(MIN('Model inputs'!AG62,'Model inputs'!AI46)-1))*'Model inputs'!AI82) -> 1000 | AH18: =IF(IF(IF(ISERROR('Model inputs'!AH62<1),'Model inputs'!AH62<1,IF('Model inputs'!AH62="","",'Model inputs'!AH62<1))="",FALSE,IF(ISERROR('Model inputs'!AH62<1),'Model inputs'!AH62<1,IF('Model inputs'!AH62="","",'Model inputs'!AH62<1))),0,'Model inputs'!AI50*IF(AND((1+'Model inputs'!AI58)=0,(MIN('Model inputs'!AH62,'Model inputs'!AI46)-1)=0),SQRT(-1),(1+'Model inputs'!AI58)^(MIN('Model inputs'!AH62,'Model inputs'!AI46)-1))*'Model inputs'!AI82) -> 1000
A19: Jobs attempted · Growth · $0.60 | B19: 0 | C19: 0 | D19: 0 | E19: 0 | F19: 0 | G19: 0 | H19: 0 | I19: 0 | J19: 0 | K19: =IF(IF(IF(ISERROR('Model inputs'!K63<1),'Model inputs'!K63<1,IF('Model inputs'!K63="","",'Model inputs'!K63<1))="",FALSE,IF(ISERROR('Model inputs'!K63<1),'Model inputs'!K63<1,IF('Model inputs'!K63="","",'Model inputs'!K63<1))),0,'Model inputs'!AI51*IF(AND((1+'Model inputs'!AI59)=0,(MIN('Model inputs'!K63,'Model inputs'!AI47)-1)=0),SQRT(-1),(1+'Model inputs'!AI59)^(MIN('Model inputs'!K63,'Model inputs'!AI47)-1))*'Model inputs'!AI83) -> 0 | L19: =IF(IF(IF(ISERROR('Model inputs'!L63<1),'Model inputs'!L63<1,IF('Model inputs'!L63="","",'Model inputs'!L63<1))="",FALSE,IF(ISERROR('Model inputs'!L63<1),'Model inputs'!L63<1,IF('Model inputs'!L63="","",'Model inputs'!L63<1))),0,'Model inputs'!AI51*IF(AND((1+'Model inputs'!AI59)=0,(MIN('Model inputs'!L63,'Model inputs'!AI47)-1)=0),SQRT(-1),(1+'Model inputs'!AI59)^(MIN('Model inputs'!L63,'Model inputs'!AI47)-1))*'Model inputs'!AI83) -> 850 | M19: =IF(IF(IF(ISERROR('Model inputs'!M63<1),'Model inputs'!M63<1,IF('Model inputs'!M63="","",'Model inputs'!M63<1))="",FALSE,IF(ISERROR('Model inputs'!M63<1),'Model inputs'!M63<1,IF('Model inputs'!M63="","",'Model inputs'!M63<1))),0,'Model inputs'!AI51*IF(AND((1+'Model inputs'!AI59)=0,(MIN('Model inputs'!M63,'Model inputs'!AI47)-1)=0),SQRT(-1),(1+'Model inputs'!AI59)^(MIN('Model inputs'!M63,'Model inputs'!AI47)-1))*'Model inputs'!AI83) -> 1062.5 | N19: =IF(IF(IF(ISERROR('Model inputs'!N63<1),'Model inputs'!N63<1,IF('Model inputs'!N63="","",'Model inputs'!N63<1))="",FALSE,IF(ISERROR('Model inputs'!N63<1),'Model inputs'!N63<1,IF('Model inputs'!N63="","",'Model inputs'!N63<1))),0,'Model inputs'!AI51*IF(AND((1+'Model inputs'!AI59)=0,(MIN('Model inputs'!N63,'Model inputs'!AI47)-1)=0),SQRT(-1),(1+'Model inputs'!AI59)^(MIN('Model inputs'!N63,'Model inputs'!AI47)-1))*'Model inputs'!AI83) -> 1328.125 | O19: =IF(IF(IF(ISERROR('Model inputs'!O63<1),'Model inputs'!O63<1,IF('Model inputs'!O63="","",'Model inputs'!O63<1))="",FALSE,IF(ISERROR('Model inputs'!O63<1),'Model inputs'!O63<1,IF('Model inputs'!O63="","",'Model inputs'!O63<1))),0,'Model inputs'!AI51*IF(AND((1+'Model inputs'!AI59)=0,(MIN('Model inputs'!O63,'Model inputs'!AI47)-1)=0),SQRT(-1),(1+'Model inputs'!AI59)^(MIN('Model inputs'!O63,'Model inputs'!AI47)-1))*'Model inputs'!AI83) -> 1660.1562 | P19: =IF(IF(IF(ISERROR('Model inputs'!P63<1),'Model inputs'!P63<1,IF('Model inputs'!P63="","",'Model inputs'!P63<1))="",FALSE,IF(ISERROR('Model inputs'!P63<1),'Model inputs'!P63<1,IF('Model inputs'!P63="","",'Model inputs'!P63<1))),0,'Model inputs'!AI51*IF(AND((1+'Model inputs'!AI59)=0,(MIN('Model inputs'!P63,'Model inputs'!AI47)-1)=0),SQRT(-1),(1+'Model inputs'!AI59)^(MIN('Model inputs'!P63,'Model inputs'!AI47)-1))*'Model inputs'!AI83) -> 2075.1953 | Q19: =IF(IF(IF(ISERROR('Model inputs'!Q63<1),'Model inputs'!Q63<1,IF('Model inputs'!Q63="","",'Model inputs'!Q63<1))="",FALSE,IF(ISERROR('Model inputs'!Q63<1),'Model inputs'!Q63<1,IF('Model inputs'!Q63="","",'Model inputs'!Q63<1))),0,'Model inputs'!AI51*IF(AND((1+'Model inputs'!AI59)=0,(MIN('Model inputs'!Q63,'Model inputs'!AI47)-1)=0),SQRT(-1),(1+'Model inputs'!AI59)^(MIN('Model inputs'!Q63,'Model inputs'!AI47)-1))*'Model inputs'!AI83) -> 2593.9941 | R19: =IF(IF(IF(ISERROR('Model inputs'!R63<1),'Model inputs'!R63<1,IF('Model inputs'!R63="","",'Model inputs'!R63<1))="",FALSE,IF(ISERROR('Model inputs'!R63<1),'Model inputs'!R63<1,IF('Model inputs'!R63="","",'Model inputs'!R63<1))),0,'Model inputs'!AI51*IF(AND((1+'Model inputs'!AI59)=0,(MIN('Model inputs'!R63,'Model inputs'!AI47)-1)=0),SQRT(-1),(1+'Model inputs'!AI59)^(MIN('Model inputs'!R63,'Model inputs'!AI47)-1))*'Model inputs'!AI83) -> 3242.4927 | S19: =IF(IF(IF(ISERROR('Model inputs'!S63<1),'Model inputs'!S63<1,IF('Model inputs'!S63="","",'Model inputs'!S63<1))="",FALSE,IF(ISERROR('Model inputs'!S63<1),'Model inputs'!S63<1,IF('Model inputs'!S63="","",'Model inputs'!S63<1))),0,'Model inputs'!AI51*IF(AND((1+'Model inputs'!AI59)=0,(MIN('Model inputs'!S63,'Model inputs'!AI47)-1)=0),SQRT(-1),(1+'Model inputs'!AI59)^(MIN('Model inputs'!S63,'Model inputs'!AI47)-1))*'Model inputs'!AI83) -> 4053.1158 | T19: =IF(IF(IF(ISERROR('Model inputs'!T63<1),'Model inputs'!T63<1,IF('Model inputs'!T63="","",'Model inputs'!T63<1))="",FALSE,IF(ISERROR('Model inputs'!T63<1),'Model inputs'!T63<1,IF('Model inputs'!T63="","",'Model inputs'!T63<1))),0,'Model inputs'!AI51*IF(AND((1+'Model inputs'!AI59)=0,(MIN('Model inputs'!T63,'Model inputs'!AI47)-1)=0),SQRT(-1),(1+'Model inputs'!AI59)^(MIN('Model inputs'!T63,'Model inputs'!AI47)-1))*'Model inputs'!AI83) -> 5066.3948 | U19: =IF(IF(IF(ISERROR('Model inputs'!U63<1),'Model inputs'!U63<1,IF('Model inputs'!U63="","",'Model inputs'!U63<1))="",FALSE,IF(ISERROR('Model inputs'!U63<1),'Model inputs'!U63<1,IF('Model inputs'!U63="","",'Model inputs'!U63<1))),0,'Model inputs'!AI51*IF(AND((1+'Model inputs'!AI59)=0,(MIN('Model inputs'!U63,'Model inputs'!AI47)-1)=0),SQRT(-1),(1+'Model inputs'!AI59)^(MIN('Model inputs'!U63,'Model inputs'!AI47)-1))*'Model inputs'!AI83) -> 6332.9935 | V19: =IF(IF(IF(ISERROR('Model inputs'!V63<1),'Model inputs'!V63<1,IF('Model inputs'!V63="","",'Model inputs'!V63<1))="",FALSE,IF(ISERROR('Model inputs'!V63<1),'Model inputs'!V63<1,IF('Model inputs'!V63="","",'Model inputs'!V63<1))),0,'Model inputs'!AI51*IF(AND((1+'Model inputs'!AI59)=0,(MIN('Model inputs'!V63,'Model inputs'!AI47)-1)=0),SQRT(-1),(1+'Model inputs'!AI59)^(MIN('Model inputs'!V63,'Model inputs'!AI47)-1))*'Model inputs'!AI83) -> 7916.2419 | W19: =IF(IF(IF(ISERROR('Model inputs'!W63<1),'Model inputs'!W63<1,IF('Model inputs'!W63="","",'Model inputs'!W63<1))="",FALSE,IF(ISERROR('Model inputs'!W63<1),'Model inputs'!W63<1,IF('Model inputs'!W63="","",'Model inputs'!W63<1))),0,'Model inputs'!AI51*IF(AND((1+'Model inputs'!AI59)=0,(MIN('Model inputs'!W63,'Model inputs'!AI47)-1)=0),SQRT(-1),(1+'Model inputs'!AI59)^(MIN('Model inputs'!W63,'Model inputs'!AI47)-1))*'Model inputs'!AI83) -> 9895.3024 | X19: =IF(IF(IF(ISERROR('Model inputs'!X63<1),'Model inputs'!X63<1,IF('Model inputs'!X63="","",'Model inputs'!X63<1))="",FALSE,IF(ISERROR('Model inputs'!X63<1),'Model inputs'!X63<1,IF('Model inputs'!X63="","",'Model inputs'!X63<1))),0,'Model inputs'!AI51*IF(AND((1+'Model inputs'!AI59)=0,(MIN('Model inputs'!X63,'Model inputs'!AI47)-1)=0),SQRT(-1),(1+'Model inputs'!AI59)^(MIN('Model inputs'!X63,'Model inputs'!AI47)-1))*'Model inputs'!AI83) -> 9895.3024 | Y19: =IF(IF(IF(ISERROR('Model inputs'!Y63<1),'Model inputs'!Y63<1,IF('Model inputs'!Y63="","",'Model inputs'!Y63<1))="",FALSE,IF(ISERROR('Model inputs'!Y63<1),'Model inputs'!Y63<1,IF('Model inputs'!Y63="","",'Model inputs'!Y63<1))),0,'Model inputs'!AI51*IF(AND((1+'Model inputs'!AI59)=0,(MIN('Model inputs'!Y63,'Model inputs'!AI47)-1)=0),SQRT(-1),(1+'Model inputs'!AI59)^(MIN('Model inputs'!Y63,'Model inputs'!AI47)-1))*'Model inputs'!AI83) -> 9895.3024 | Z19: =IF(IF(IF(ISERROR('Model inputs'!Z63<1),'Model inputs'!Z63<1,IF('Model inputs'!Z63="","",'Model inputs'!Z63<1))="",FALSE,IF(ISERROR('Model inputs'!Z63<1),'Model inputs'!Z63<1,IF('Model inputs'!Z63="","",'Model inputs'!Z63<1))),0,'Model inputs'!AI51*IF(AND((1+'Model inputs'!AI59)=0,(MIN('Model inputs'!Z63,'Model inputs'!AI47)-1)=0),SQRT(-1),(1+'Model inputs'!AI59)^(MIN('Model inputs'!Z63,'Model inputs'!AI47)-1))*'Model inputs'!AI83) -> 9895.3024 | AA19: =IF(IF(IF(ISERROR('Model inputs'!AA63<1),'Model inputs'!AA63<1,IF('Model inputs'!AA63="","",'Model inputs'!AA63<1))="",FALSE,IF(ISERROR('Model inputs'!AA63<1),'Model inputs'!AA63<1,IF('Model inputs'!AA63="","",'Model inputs'!AA63<1))),0,'Model inputs'!AI51*IF(AND((1+'Model inputs'!AI59)=0,(MIN('Model inputs'!AA63,'Model inputs'!AI47)-1)=0),SQRT(-1),(1+'Model inputs'!AI59)^(MIN('Model inputs'!AA63,'Model inputs'!AI47)-1))*'Model inputs'!AI83) -> 9895.3024 | AB19: =IF(IF(IF(ISERROR('Model inputs'!AB63<1),'Model inputs'!AB63<1,IF('Model inputs'!AB63="","",'Model inputs'!AB63<1))="",FALSE,IF(ISERROR('Model inputs'!AB63<1),'Model inputs'!AB63<1,IF('Model inputs'!AB63="","",'Model inputs'!AB63<1))),0,'Model inputs'!AI51*IF(AND((1+'Model inputs'!AI59)=0,(MIN('Model inputs'!AB63,'Model inputs'!AI47)-1)=0),SQRT(-1),(1+'Model inputs'!AI59)^(MIN('Model inputs'!AB63,'Model inputs'!AI47)-1))*'Model inputs'!AI83) -> 9895.3024 | AC19: =IF(IF(IF(ISERROR('Model inputs'!AC63<1),'Model inputs'!AC63<1,IF('Model inputs'!AC63="","",'Model inputs'!AC63<1))="",FALSE,IF(ISERROR('Model inputs'!AC63<1),'Model inputs'!AC63<1,IF('Model inputs'!AC63="","",'Model inputs'!AC63<1))),0,'Model inputs'!AI51*IF(AND((1+'Model inputs'!AI59)=0,(MIN('Model inputs'!AC63,'Model inputs'!AI47)-1)=0),SQRT(-1),(1+'Model inputs'!AI59)^(MIN('Model inputs'!AC63,'Model inputs'!AI47)-1))*'Model inputs'!AI83) -> 9895.3024 | AD19: =IF(IF(IF(ISERROR('Model inputs'!AD63<1),'Model inputs'!AD63<1,IF('Model inputs'!AD63="","",'Model inputs'!AD63<1))="",FALSE,IF(ISERROR('Model inputs'!AD63<1),'Model inputs'!AD63<1,IF('Model inputs'!AD63="","",'Model inputs'!AD63<1))),0,'Model inputs'!AI51*IF(AND((1+'Model inputs'!AI59)=0,(MIN('Model inputs'!AD63,'Model inputs'!AI47)-1)=0),SQRT(-1),(1+'Model inputs'!AI59)^(MIN('Model inputs'!AD63,'Model inputs'!AI47)-1))*'Model inputs'!AI83) -> 9895.3024 | AE19: =IF(IF(IF(ISERROR('Model inputs'!AE63<1),'Model inputs'!AE63<1,IF('Model inputs'!AE63="","",'Model inputs'!AE63<1))="",FALSE,IF(ISERROR('Model inputs'!AE63<1),'Model inputs'!AE63<1,IF('Model inputs'!AE63="","",'Model inputs'!AE63<1))),0,'Model inputs'!AI51*IF(AND((1+'Model inputs'!AI59)=0,(MIN('Model inputs'!AE63,'Model inputs'!AI47)-1)=0),SQRT(-1),(1+'Model inputs'!AI59)^(MIN('Model inputs'!AE63,'Model inputs'!AI47)-1))*'Model inputs'!AI83) -> 9895.3024 | AF19: =IF(IF(IF(ISERROR('Model inputs'!AF63<1),'Model inputs'!AF63<1,IF('Model inputs'!AF63="","",'Model inputs'!AF63<1))="",FALSE,IF(ISERROR('Model inputs'!AF63<1),'Model inputs'!AF63<1,IF('Model inputs'!AF63="","",'Model inputs'!AF63<1))),0,'Model inputs'!AI51*IF(AND((1+'Model inputs'!AI59)=0,(MIN('Model inputs'!AF63,'Model inputs'!AI47)-1)=0),SQRT(-1),(1+'Model inputs'!AI59)^(MIN('Model inputs'!AF63,'Model inputs'!AI47)-1))*'Model inputs'!AI83) -> 9895.3024 | AG19: =IF(IF(IF(ISERROR('Model inputs'!AG63<1),'Model inputs'!AG63<1,IF('Model inputs'!AG63="","",'Model inputs'!AG63<1))="",FALSE,IF(ISERROR('Model inputs'!AG63<1),'Model inputs'!AG63<1,IF('Model inputs'!AG63="","",'Model inputs'!AG63<1))),0,'Model inputs'!AI51*IF(AND((1+'Model inputs'!AI59)=0,(MIN('Model inputs'!AG63,'Model inputs'!AI47)-1)=0),SQRT(-1),(1+'Model inputs'!AI59)^(MIN('Model inputs'!AG63,'Model inputs'!AI47)-1))*'Model inputs'!AI83) -> 9895.3024 | AH19: =IF(IF(IF(ISERROR('Model inputs'!AH63<1),'Model inputs'!AH63<1,IF('Model inputs'!AH63="","",'Model inputs'!AH63<1))="",FALSE,IF(ISERROR('Model inputs'!AH63<1),'Model inputs'!AH63<1,IF('Model inputs'!AH63="","",'Model inputs'!AH63<1))),0,'Model inputs'!AI51*IF(AND((1+'Model inputs'!AI59)=0,(MIN('Model inputs'!AH63,'Model inputs'!AI47)-1)=0),SQRT(-1),(1+'Model inputs'!AI59)^(MIN('Model inputs'!AH63,'Model inputs'!AI47)-1))*'Model inputs'!AI83) -> 9895.3024
